Workbook

Sheet Summary
A1: DuPage County 2025 Tax Sale – Revised Bid Totals
A2: Removed: certs under $3,000 where both installments are delinquent (HalfInstallment = FALSE). Commercial = ClassCode "60 - Commercial Improvements".
A4: Category | B4: Cert Count | C4: Dollar Amount
A5: Revised Non-Commercial (Residential) | B5: =COUNTA('Revised Non-Commercial'!L2:L10000) -> 1142 | C5: =SUMIFS('Revised Non-Commercial'!AC2:AC10000,'Revised Non-Commercial'!L2:L10000,"<>") -> 8273859.2
A6: Commercial | B6: =COUNTA(Commercial!L2:L10000) -> 23 | C6: =SUMIFS(Commercial!AC2:AC10000,Commercial!L2:L10000,"<>") -> 1053093.8
A7: Revised Total (keep) | B7: =B5+B6 -> 1165 | C7: =C5+C6 -> 9326953
A9: Removed – Full Inst Under $3,000 | B9: =COUNTA('Removed - Full Inst Under 3K'!L2:L10000) -> 73 | C9: =SUMIFS('Removed - Full Inst Under 3K'!AC2:AC10000,'Removed - Full Inst Under 3K'!L2:L10000,"<>") -> 156875.76
A10: Original Bid List Total | B10: =B7+B9 -> 1238 | C10: =C7+C9 -> 9483828.8
A12: Flags in revised list
A13: 2024 comment "DNB-Open Sold Taxes" (Revised Non-Commercial) | B13: =COUNTIFS('Revised Non-Commercial'!F2:F10000,"DNB*") -> 8 | C13: =SUMIFS('Revised Non-Commercial'!AC2:AC10000,'Revised Non-Commercial'!F2:F10000,"DNB*") -> 57415.35
A14: 2024 comment "DNB-Open Sold Taxes" (Commercial) | B14: =COUNTIFS(Commercial!F2:F10000,"DNB*") -> 0 | C14: =SUMIFS(Commercial!AC2:AC10000,Commercial!F2:F10000,"DNB*") -> 0

Sheet Revised Non-Commercial
A1: Ok to Buy | B1: Do Not Buy | C1: TempBid | D1: Bid | E1: Comment | F1: 2024Comment | G1: 2024Bid | H1: 2023OkToBuy | I1: 2023DoNotBuy | J1: 2023Comment | K1: Taxpayer Name | L1: Parcel Number | M1: PINNoDashes | N1: Assessed Land | O1: Assessed Bldg | P1: ClassCode | Q1: SaleAmt | R1: SaleDt | S1: MortAmt | T1: MortDt | U1: 2ndMort | V1: 2ndMortDt | W1: Lien | X1: Judgmt | Y1: Property Address 1 | Z1: Property City | AA1: Back Tax | AB1: TotalTaxBilled | AC1: Judgment Amount | AD1: HalfInstallment
A2: =TRUE() -> TRUE | B2: =FALSE() -> FALSE | C2: 2 | G2: 3 | H2: =FALSE() -> FALSE | I2: =FALSE() -> FALSE | K2: PATEL INDIRA | L2: 01-01-205-018 | M2: 0101205018 | N2: 19344 | O2: 78179 | P2: 40 - Residential Improvements | Q2: 143500 | R2: 34898 | W2: N | X2: N | Y2: 1634 OAK ST | Z2: HANOVER PARK | AA2: 0 | AB2: 7474.54 | AC2: 7989.07 | AD2: =FALSE() -> FALSE
A3: =TRUE() -> TRUE | B3: =FALSE() -> FALSE | C3: 2 | H3: =FALSE() -> FALSE | I3: =FALSE() -> FALSE | K3: GRAVINA VINCENZO | L3: 01-01-425-032 | M3: 0101425032 | N3: 17999 | O3: 63222 | P3: 40 - Residential Improvements | Q3: 130000 | R3: 35107 | W3: N | X3: N | Y3: 1239 DUNAMON DR | Z3: BARTLETT | AA3: 0 | AB3: 6566.96 | AC3: 3441.24 | AD3: =TRUE() -> TRUE
A4: =TRUE() -> TRUE | B4: =FALSE() -> FALSE | C4: 3 | H4: =FALSE() -> FALSE | I4: =FALSE() -> FALSE | K4: KENNEDY MICHAEL | L4: 01-02-200-012 | M4: 0102200012 | N4: 34212 | O4: 88198 | P4: 40 - Residential Improvements | Q4: 185000 | R4: 43894 | W4: N | X4: Y | Y4: 716 BALBOA TER W | Z4: BARTLETT | AA4: 0 | AB4: 9897.22 | AC4: 10575.28 | AD4: =FALSE() -> FALSE
A5: =TRUE() -> TRUE | B5: =FALSE() -> FALSE | C5: 2 | H5: =FALSE() -> FALSE | I5: =FALSE() -> FALSE | K5: CABRAL PORFIRIO & F P | L5: 01-02-201-129 | M5: 0102201129 | N5: 33915 | O5: 77606 | P5: 40 - Residential Improvements | S5: 186000 | T5: 38335 | W5: N | X5: N | Y5: 446 HARBOR TER | Z5: BARTLETT | AA5: 0 | AB5: 7723.16 | AC5: 4045.35 | AD5: =TRUE() -> TRUE
A6: =TRUE() -> TRUE | B6: =FALSE() -> FALSE | C6: 2 | H6: =FALSE() -> FALSE | I6: =FALSE() -> FALSE | K6: SHAHY LLC | L6: 01-02-203-010 | M6: 0102203010 | N6: 33992 | O6: 77992 | P6: 40 - Residential Improvements | Q6: 290000 | R6: 45729 | W6: N | X6: N | Y6: 742 VOYAGER DR | Z6: BARTLETT | AA6: 0 | AB6: 8407.42 | AC6: 8984.92 | AD6: =FALSE() -> FALSE
A7: =TRUE() -> TRUE | B7: =FALSE() -> FALSE | C7: 3 | G7: 2 | H7: =TRUE() -> TRUE | I7: =FALSE() -> FALSE | K7: KOHL SCOTT & ANDREA | L7: 01-02-414-012 | M7: 0102414012 | N7: 36340 | O7: 95704 | P7: 40 - Residential Improvements | Q7: 339000 | R7: 38692 | S7: 252000 | T7: 40617 | W7: N | X7: Y | Y7: 951 TALLGRASS DR | Z7: BARTLETT | AA7: 0 | AB7: 10029.34 | AC7: 10716.32 | AD7: =FALSE() -> FALSE
A8: =TRUE() -> TRUE | B8: =FALSE() -> FALSE | C8: 3 | G8: 3 | H8: =TRUE() -> TRUE | I8: =FALSE() -> FALSE | K8: MILLER JONATHAN & JAMIE | L8: 01-03-104-017 | M8: 0103104017 | N8: 53975 | O8: 120559 | P8: 40 - Residential Improvements | Q8: 355000 | R8: 37847 | W8: N | X8: Y | Y8: 707 BRAINTREE LN | Z8: BARTLETT | AA8: 0 | AB8: 14111.6 | AC8: 15074.13 | AD8: =FALSE() -> FALSE
A9: =TRUE() -> TRUE | B9: =FALSE() -> FALSE | C9: 2 | H9: =FALSE() -> FALSE | I9: =FALSE() -> FALSE | K9: GABRICH F & T &D GARRICK | L9: 01-03-304-030 | M9: 0103304030 | N9: 36317 | O9: 73869 | P9: 40 - Residential Improvements | Y9: 936 CUYAHOGA TERR | Z9: BARTLETT | AA9: 0 | AB9: 7615.22 | AC9: 3988.95 | AD9: =TRUE() -> TRUE
A10: =TRUE() -> TRUE | B10: =FALSE() -> FALSE | C10: 2 | H10: =TRUE() -> TRUE | I10: =FALSE() -> FALSE | K10: BATOZHYNSKA YANA | L10: 01-09-415-007 | M10: 0109415007 | N10: 39128 | O10: 116988 | P10: 40 - Residential Improvements | Q10: 358000 | R10: 43522 | S10: 334000 | T10: 44145 | W10: N | X10: N | Y10: 1120 THOUSAND OAKS DR | Z10: BARTLETT | AA10: 0 | AB10: 11975.64 | AC10: 6267.27 | AD10: =TRUE() -> TRUE
A11: =TRUE() -> TRUE | B11: =FALSE() -> FALSE | C11: 2 | H11: =FALSE() -> FALSE | I11: =FALSE() -> FALSE | K11: CONCEPCION CARLOS DELA | L11: 01-09-415-022 | M11: 0109415022 | N11: 35149 | O11: 95241 | P11: 40 - Residential Improvements | Q11: 267500 | R11: 42094 | S11: 194000 | T11: 44140 | W11: N | X11: N | Y11: 1189 CHARTER OAKS DR | Z11: BARTLETT | AA11: 0 | AB11: 9895.6 | AC11: 5180.45 | AD11: =TRUE() -> TRUE
A12: =TRUE() -> TRUE | B12: =FALSE() -> FALSE | C12: 3 | H12: =FALSE() -> FALSE | I12: =FALSE() -> FALSE | K12: FARIAS REBECCA & ADELINE | L12: 01-10-102-023 | M12: 0110102023 | N12: 33518 | O12: 65107 | P12: 40 - Residential Improvements | S12: 100000 | T12: 42858 | U12: 46000 | V12: 35822 | W12: N | X12: N | Y12: 968 LAKEWOOD DR | Z12: BARTLETT | AA12: 0 | AB12: 7327.32 | AC12: 7831.91 | AD12: =FALSE() -> FALSE
A13: =TRUE() -> TRUE | B13: =FALSE() -> FALSE | C13: 3 | H13: =TRUE() -> TRUE | I13: =FALSE() -> FALSE | K13: FIEROH NANCY J | L13: 01-10-104-002 | M13: 0110104002 | N13: 36317 | O13: 79667 | P13: 40 - Residential Improvements | Q13: 200000 | R13: 37154 | S13: 62000 | T13: 43034 | W13: N | X13: N | Y13: 835 BRYN MAWR AVE | Z13: BARTLETT | AA13: 0 | AB13: 8084.04 | AC13: 8639.71 | AD13: =FALSE() -> FALSE
A14: =TRUE() -> TRUE | B14: =FALSE() -> FALSE | C14: 2 | H14: =FALSE() -> FALSE | I14: =FALSE() -> FALSE | K14: LOFDAHL SANDRA L & D J | L14: 01-11-109-008 | M14: 0111109008 | N14: 27368 | O14: 121540 | P14: 40 - Residential Improvements | Q14: 392000 | R14: 38917 | S14: 295143 | T14: 40485 | U14: 39191 | V14: 38917 | W14: N | X14: Y | Y14: 985 HUMMINGBIRD WAY # 43/B | Z14: BARTLETT | AA14: 0 | AB14: 11392.84 | AC14: 5962.76 | AD14: =TRUE() -> TRUE
A15: =TRUE() -> TRUE | B15: =FALSE() -> FALSE | C15: 2 | H15: =FALSE() -> FALSE | I15: =FALSE() -> FALSE | K15: ANDRADE ROLANDO | L15: 01-11-200-024 | M15: 0111200024 | N15: 33838 | O15: 70794 | P15: 40 - Residential Improvements | Q15: 144000 | R15: 36172 | W15: N | X15: Y | Y15: 258 JACKSON CT | Z15: BARTLETT | AA15: 0 | AB15: 7812.98 | AC15: 8350.35 | AD15: =FALSE() -> FALSE
A16: =TRUE() -> TRUE | B16: =FALSE() -> FALSE | C16: 2 | H16: =FALSE() -> FALSE | I16: =FALSE() -> FALSE | K16: MIROWSKI RAYMOND | L16: 01-12-107-020 | M16: 0112107020 | N16: 32779 | O16: 55297 | P16: 40 - Residential Improvements | Q16: 279000 | R16: 45380 | W16: N | X16: Y | Y16: 5356 NIVEN LN | Z16: HANOVER PARK | AA16: 0 | AB16: 6705.96 | AC16: 7168.61 | AD16: =FALSE() -> FALSE
A17: =TRUE() -> TRUE | B17: =FALSE() -> FALSE | C17: 3 | H17: =FALSE() -> FALSE | I17: =FALSE() -> FALSE | K17: THAKKAR JIGAR & SHRADDHA | L17: 01-12-210-022 | M17: 0112210022 | N17: 33926 | O17: 83117 | P17: 40 - Residential Improvements | Q17: 221000 | R17: 42530 | S17: 221000 | T17: 42530 | W17: N | X17: N | Y17: 1915 LUCILLE LN | Z17: HANOVER PARK | AA17: 0 | AB17: 9772.28 | AC17: 10441.91 | AD17: =FALSE() -> FALSE
A18: =TRUE() -> TRUE | B18: =FALSE() -> FALSE | C18: 2 | H18: =TRUE() -> TRUE | I18: =FALSE() -> FALSE | K18: MARTINEZ MARTHA E | L18: 01-13-103-059 | M18: 0113103059 | N18: 14825 | O18: 60544 | P18: 40 - Residential Improvements | Q18: 194000 | R18: 44074 | W18: N | X18: N | Y18: 2151 ROB ROY CT | Z18: HANOVER PARK | AA18: 0 | AB18: 5641.82 | AC18: 6032.64 | AD18: =FALSE() -> FALSE
A19: =TRUE() -> TRUE | B19: =FALSE() -> FALSE | C19: 2 | H19: =FALSE() -> FALSE | I19: =FALSE() -> FALSE | K19: JOHNSON ROBERT L | L19: 01-13-104-056 | M19: 0113104056 | N19: 14825 | O19: 60544 | P19: 40 - Residential Improvements | W19: N | X19: N | Y19: 2119 GLASGOW CT | Z19: HANOVER PARK | AA19: 0 | AB19: 4971.86 | AC19: 5317.46 | AD19: =FALSE() -> FALSE
A20: =TRUE() -> TRUE | B20: =FALSE() -> FALSE | C20: 2 | G20: 3 | H20: =FALSE() -> FALSE | I20: =FALSE() -> FALSE | K20: SINGH KAMLA | L20: 01-13-107-028 | M20: 0113107028 | N20: 34345 | O20: 96145 | P20: 40 - Residential Improvements | Q20: 260000 | R20: 39049 | W20: N | X20: Y | Y20: 4695 GREEN BRIDGE LN | Z20: HANOVER PARK | AA20: 0 | AB20: 10927.9 | AC20: 5719.83 | AD20: =TRUE() -> TRUE
A21: =TRUE() -> TRUE | B21: =FALSE() -> FALSE | C21: 2 | H21: =FALSE() -> FALSE | I21: =FALSE() -> FALSE | K21: ROSTRON MICHAEL | L21: 01-13-126-040 | M21: 0113126040 | N21: 13733 | O21: 70882 | P21: 40 - Residential Improvements | Q21: 139500 | R21: 34628 | S21: 142000 | T21: 43647 | U21: 12800 | V21: 37071 | W21: N | X21: Y | Y21: 1628 COLUMBIA CIR # 3 | Z21: BARTLETT | AA21: 0 | AB21: 6194.56 | AC21: 3246.66 | AD21: =TRUE() -> TRUE
A22: =TRUE() -> TRUE | B22: =FALSE() -> FALSE | C22: 2 | H22: =FALSE() -> FALSE | I22: =FALSE() -> FALSE | K22: CHICAGO TITLE LAND TRUST CO | L22: 01-13-213-074 | M22: 0113213074 | N22: 14935 | O22: 58251 | P22: 40 - Residential Improvements | Q22: 100000 | R22: 45636 | W22: N | X22: N | Y22: 4413 BELL LN | Z22: HANOVER PARK | AA22: 0 | AB22: 5294.98 | AC22: 5662.39 | AD22: =FALSE() -> FALSE
A23: =TRUE() -> TRUE | B23: =FALSE() -> FALSE | C23: 2 | H23: =FALSE() -> FALSE | I23: =FALSE() -> FALSE | K23: THAKKAR SANJANA | L23: 01-13-215-043 | M23: 0113215043 | N23: 14935 | O23: 56598 | P23: 40 - Residential Improvements | Q23: 225000 | R23: 44715 | S23: 168750 | T23: 44715 | W23: N | X23: N | Y23: 4723 JEFFERSON ST | Z23: HANOVER PARK | AA23: 0 | AB23: 6623.4 | AC23: 3470.73 | AD23: =TRUE() -> TRUE
A24: =TRUE() -> TRUE | B24: =FALSE() -> FALSE | C24: 2 | H24: =FALSE() -> FALSE | I24: =FALSE() -> FALSE | K24: SMITH BRIAN | L24: 01-13-309-013 | M24: 0113309013 | N24: 31798 | O24: 79744 | P24: 40 - Residential Improvements | Q24: 238000 | R24: 38225 | S24: 190400 | T24: 38300 | U24: 88700 | V24: 38918 | W24: N | X24: Y | Y24: 2284 HARBOR LN | Z24: HANOVER PARK | AA24: 0 | AB24: 8645.04 | AC24: 4527.03 | AD24: =TRUE() -> TRUE
A25: =TRUE() -> TRUE | B25: =FALSE() -> FALSE | C25: 3 | H25: =FALSE() -> FALSE | I25: =FALSE() -> FALSE | K25: PATEL JEETENDRA | L25: 01-13-312-053 | M25: 0113312053 | N25: 34345 | O25: 86490 | P25: 40 - Residential Improvements | Q25: 209000 | R25: 36657 | W25: Y | X25: N | Y25: 4060 PENNSBURY CT | Z25: HANOVER PARK | AA25: 0 | AB25: 10088.88 | AC25: 10779.88 | AD25: =FALSE() -> FALSE
A26: =TRUE() -> TRUE | B26: =FALSE() -> FALSE | C26: 3 | G26: 2 | H26: =FALSE() -> FALSE | I26: =FALSE() -> FALSE | K26: MCINERNEY PATRICK & C A | L26: 01-13-403-064 | M26: 0113403064 | N26: 36417 | O26: 74134 | P26: 40 - Residential Improvements | Q26: 161000 | R26: 35608 | S26: 168000 | T26: 41766 | U26: 10500 | V26: 41856 | W26: Y | X26: N | Y26: 4015 TORONTO CT | Z26: HANOVER PARK | AA26: 0 | AB26: 9495.4 | AC26: 10146.34 | AD26: =FALSE() -> FALSE
A27: =TRUE() -> TRUE | B27: =FALSE() -> FALSE | C27: 3 | H27: =FALSE() -> FALSE | I27: =FALSE() -> FALSE | K27: KIEU CU | L27: 01-13-412-014 | M27: 0113412014 | N27: 36417 | O27: 86666 | P27: 40 - Residential Improvements | Q27: 390000 | R27: 45505 | S27: 195000 | T27: 45505 | W27: N | X27: N | Y27: 1874 PASTORAL LN | Z27: HANOVER PARK | AA27: 0 | AB27: 10655.78 | AC27: 11385.05 | AD27: =FALSE() -> FALSE
A28: =TRUE() -> TRUE | B28: =FALSE() -> FALSE | C28: 3 | H28: =TRUE() -> TRUE | I28: =FALSE() -> FALSE | K28: ELLISON JASON | L28: 01-15-100-010 | M28: 0115100010 | N28: 95010 | O28: 141500 | P28: 40 - Residential Improvements | Q28: 550000 | R28: 42709 | W28: Y | X28: Y | Y28: 29W520 SCHICK RD | Z28: BARTLETT | AA28: 0 | AB28: 15724 | AC28: 16795.37 | AD28: =FALSE() -> FALSE
A29: =TRUE() -> TRUE | B29: =FALSE() -> FALSE | C29: 3 | H29: =FALSE() -> FALSE | I29: =FALSE() -> FALSE | K29: HUBLER JUSTIN & ASHLIE HARPE | L29: 01-18-210-019 | M29: 0118210019 | N29: 40704 | O29: 113681 | P29: 40 - Residential Improvements | Q29: 725000 | R29: 45601 | S29: 580000 | T29: 45601 | W29: N | X29: N | Y29: 32W224 ARMY TRAIL RD | Z29: WAYNE | AA29: 0 | AB29: 10402.84 | AC29: 11115.03 | AD29: =FALSE() -> FALSE
A30: =TRUE() -> TRUE | B30: =FALSE() -> FALSE | C30: 3 | H30: =FALSE() -> FALSE | I30: =FALSE() -> FALSE | K30: KANCHWALA ALI | L30: 01-19-102-027 | M30: 0119102027 | N30: 41762 | O30: 146251 | P30: 40 - Residential Improvements | Q30: 436500 | R30: 37375 | S30: 242500 | T30: 43913 | W30: N | X30: Y | Y30: 2647 BAINBRIDGE BLVD | Z30: WEST CHICAGO | AA30: 0 | AB30: 13726.36 | AC30: 14662.89 | AD30: =FALSE() -> FALSE
A31: =TRUE() -> TRUE | B31: =FALSE() -> FALSE | C31: 3 | G31: 3 | H31: =FALSE() -> FALSE | I31: =FALSE() -> FALSE | K31: PATEL SAMEERKUMAR & J & L | L31: 01-19-302-043 | M31: 0119302043 | N31: 37398 | O31: 101458 | P31: 40 - Residential Improvements | Q31: 4042000 | R31: 44887 | S31: 390630 | T31: 45350 | W31: N | X31: N | Y31: 2599 BARNHART ST | Z31: WEST CHICAGO | AA31: 0 | AB31: 9978.04 | AC31: 10661.56 | AD31: =FALSE() -> FALSE
A32: =TRUE() -> TRUE | B32: =FALSE() -> FALSE | C32: 3 | H32: =FALSE() -> FALSE | I32: =FALSE() -> FALSE | K32: AVILA MARTIN & B REYES | L32: 01-19-307-025 | M32: 0119307025 | N32: 37398 | O32: 94580 | P32: 40 - Residential Improvements | Q32: 262000 | R32: 41379 | S32: 180000 | T32: 45408 | W32: N | X32: N | Y32: 2915 CULVER LN | Z32: WEST CHICAGO | AA32: 0 | AB32: 9453.58 | AC32: 10101.7 | AD32: =FALSE() -> FALSE
A33: =TRUE() -> TRUE | B33: =FALSE() -> FALSE | C33: 3 | G33: 3 | H33: =FALSE() -> FALSE | I33: =FALSE() -> FALSE | K33: MOTTASHED ELIZABETH | L33: 01-20-406-006 | M33: 0120406006 | N33: 54482 | O33: 212614 | P33: 40 - Residential Improvements | Q33: 695000 | R33: 37260 | S33: 450000 | T33: 37260 | W33: N | X33: Y | Y33: 31W181 PRAIRIE LN | Z33: WAYNE | AA33: 0 | AB33: 19805.82 | AC33: 21152.71 | AD33: =FALSE() -> FALSE
A34: =TRUE() -> TRUE | B34: =FALSE() -> FALSE | C34: 3 | H34: =FALSE() -> FALSE | I34: =FALSE() -> FALSE | K34: EVANS FLEM E & DONNA | L34: 01-20-407-006 | M34: 0120407006 | N34: 67190 | O34: 187661 | P34: 40 - Residential Improvements | R34: 37861 | S34: 442000 | T34: 44321 | W34: N | X34: N | Y34: 4N050 LAKE ELEANOR CT | Z34: WAYNE | AA34: 0 | AB34: 18258.26 | AC34: 19500.69 | AD34: =FALSE() -> FALSE
A35: =TRUE() -> TRUE | B35: =FALSE() -> FALSE | C35: 2 | G35: 2 | H35: =FALSE() -> FALSE | I35: =FALSE() -> FALSE | K35: MATUSZEWSKI BEATA & G | L35: 01-23-411-004 | M35: 0123411004 | N35: 14670 | O35: 72734 | P35: 40 - Residential Improvements | Q35: 134500 | R35: 36725 | W35: N | X35: N | Y35: 1164 ROBIN DR | Z35: CAROL STREAM | AA35: 0 | AB35: 6087.52 | AC35: 6508.43 | AD35: =FALSE() -> FALSE
A36: =TRUE() -> TRUE | B36: =FALSE() -> FALSE | C36: 2 | G36: 2 | H36: =FALSE() -> FALSE | I36: =FALSE() -> FALSE | K36: STROLE MICHELLE | L36: 01-23-411-012 | M36: 0123411012 | N36: 14670 | O36: 76592 | P36: 40 - Residential Improvements | Q36: 231000 | R36: 43789 | W36: N | X36: N | Y36: 1186 ROBIN DR | Z36: CAROL STREAM | AA36: 0 | AB36: 6383.28 | AC36: 6824.15 | AD36: =FALSE() -> FALSE
A37: =TRUE() -> TRUE | B37: =FALSE() -> FALSE | C37: 2 | H37: =FALSE() -> FALSE | I37: =FALSE() -> FALSE | K37: KAMALIA MANOJ P & MANJU | L37: 01-24-107-018 | M37: 0124107018 | N37: 14847 | O37: 62781 | P37: 40 - Residential Improvements | S37: 20000 | T37: 35947 | W37: N | X37: N | Y37: 3901 SPRINGLAKE DR | Z37: HANOVER PARK | AA37: 0 | AB37: 6481.4 | AC37: 3396.53 | AD37: =TRUE() -> TRUE
A38: =TRUE() -> TRUE | B38: =FALSE() -> FALSE | C38: 2 | H38: =FALSE() -> FALSE | I38: =FALSE() -> FALSE | K38: ROMAN ANTONIO & VERONICA | L38: 01-24-113-032 | M38: 0124113032 | N38: 14847 | O38: 71687 | P38: 40 - Residential Improvements | Q38: 155000 | R38: 37533 | S38: 124000 | T38: 37533 | W38: Y | X38: N | Y38: 2112 WINDWARD LN | Z38: HANOVER PARK | AA38: 0 | AB38: 6368.36 | AC38: 3337.47 | AD38: =TRUE() -> TRUE
A39: =TRUE() -> TRUE | B39: =FALSE() -> FALSE | C39: 3 | G39: 2 | H39: =TRUE() -> TRUE | I39: =FALSE() -> FALSE | K39: WEST SUBURBAN BK 14147 | L39: 01-24-116-004 | M39: 0124116004 | N39: 13921 | O39: 69846 | P39: 40 - Residential Improvements | S39: 60000 | T39: 38085 | W39: N | X39: Y | Y39: 1323 GLOUCESTER CIR | Z39: CAROL STREAM | AA39: 0 | AB39: 5808.68 | AC39: 6210.77 | AD39: =FALSE() -> FALSE
A40: =TRUE() -> TRUE | B40: =FALSE() -> FALSE | C40: 2 | H40: =FALSE() -> FALSE | I40: =FALSE() -> FALSE | K40: NAWAB SYED & G SULTANA | L40: 01-24-118-014 | M40: 0124118014 | N40: 38213 | O40: 98085 | P40: 40 - Residential Improvements | Q40: 217500 | R40: 36699 | S40: 211000 | T40: 38026 | W40: N | X40: N | Y40: 1304 WOODLAKE DR | Z40: CAROL STREAM | AA40: 0 | AB40: 9835.96 | AC40: 5149.29 | AD40: =TRUE() -> TRUE
...

Sheet Commercial
A1: Ok to Buy | B1: Do Not Buy | C1: TempBid | D1: Bid | E1: Comment | F1: 2024Comment | G1: 2024Bid | H1: 2023OkToBuy | I1: 2023DoNotBuy | J1: 2023Comment | K1: Taxpayer Name | L1: Parcel Number | M1: PINNoDashes | N1: Assessed Land | O1: Assessed Bldg | P1: ClassCode | Q1: SaleAmt | R1: SaleDt | S1: MortAmt | T1: MortDt | U1: 2ndMort | V1: 2ndMortDt | W1: Lien | X1: Judgmt | Y1: Property Address 1 | Z1: Property City | AA1: Back Tax | AB1: TotalTaxBilled | AC1: Judgment Amount | AD1: HalfInstallment
A2: =TRUE() -> TRUE | B2: =FALSE() -> FALSE | C2: 4 | D2: 4 | F2: strip center | G2: 4 | H2: =FALSE() -> FALSE | I2: =FALSE() -> FALSE | K2: MILLION WAYS SERIES LLC | L2: 02-02-317-002 | M2: 0202317002 | N2: 291035 | O2: 763001 | P2: 60 - Commercial Improvements | Q2: 3000000 | R2: 43662 | W2: N | X2: N | Y2: 610 E IRVING PARK RD | Z2: ROSELLE | AA2: 0 | AB2: 67316.02 | AC2: 71869.85 | AD2: =FALSE() -> FALSE
A3: =TRUE() -> TRUE | B3: =FALSE() -> FALSE | C3: 3 | D3: 3 | G3: 3 | H3: =TRUE() -> TRUE | I3: =FALSE() -> FALSE | K3: MANGY DAWG ROSELLE INC | L3: 02-03-213-002 | M3: 0203213002 | N3: 17540 | O3: 229865 | P3: 60 - Commercial Improvements | Q3: 625000 | R3: 43894 | W3: Y | X3: N | Y3: 101-03 E IRVING PARK RD | Z3: ROSELLE | AA3: 0 | AB3: 18591.76 | AC3: 9724.19 | AD3: =TRUE() -> TRUE
A4: =TRUE() -> TRUE | B4: =FALSE() -> FALSE | C4: 5 | D4: 5 | E4: hotel | H4: =TRUE() -> TRUE | I4: =FALSE() -> FALSE | K4: IHP HOSPITALITY LLC | L4: 03-05-200-031 | M4: 0305200031 | N4: 882130 | O4: 1968140 | P4: 60 - Commercial Improvements | Q4: 7375000 | R4: 44755 | S4: 3923700 | T4: 44755 | U4: 2419000 | V4: 44820 | W4: Y | X4: N | Y4: 1150 N ARLINGTON HTS | Z4: ITASCA | AA4: 0 | AB4: 206433.66 | AC4: 220377.93 | AD4: =FALSE() -> FALSE
A5: =TRUE() -> TRUE | B5: =FALSE() -> FALSE | C5: 3 | D5: 3 | H5: =TRUE() -> TRUE | I5: =FALSE() -> FALSE | K5: EDWINBERRY PROPERTIES LLC | L5: 05-09-107-004 | M5: 0509107004 | N5: 49866 | O5: 129162 | P5: 60 - Commercial Improvements | Q5: 490000 | R5: 44140 | S5: 450000 | T5: 44140 | U5: 208000 | V5: 44144 | W5: N | X5: N | Y5: 1600 N MAIN ST | Z5: WHEATON | AA5: 0 | AB5: 11538.72 | AC5: 12327.58 | AD5: =FALSE() -> FALSE
A6: =TRUE() -> TRUE | B6: =FALSE() -> FALSE | C6: 3 | D6: 3 | F6: apts | G6: 4 | H6: =FALSE() -> FALSE | I6: =FALSE() -> FALSE | K6: MILLION WAYS SERIES LLC | L6: 06-08-100-009 | M6: 0608100009 | N6: 35427 | O6: 362312 | P6: 60 - Commercial Improvements | R6: 43157 | S6: 2000000 | T6: 44230 | W6: Y | X6: Y | Y6: 9 N MAIN ST | Z6: LOMBARD | AA6: 0 | AB6: 30902.32 | AC6: 32998.22 | AD6: =FALSE() -> FALSE
A7: =TRUE() -> TRUE | B7: =FALSE() -> FALSE | C7: 3 | D7: 3 | F7: brewing company - store | G7: 3 | H7: =FALSE() -> FALSE | I7: =FALSE() -> FALSE | K7: TRIARC DEVELOPMENT LLC | L7: 06-08-105-013 | M7: 0608105013 | N7: 68139 | O7: 70410 | P7: 60 - Commercial Improvements | Q7: 470000 | R7: 38995 | W7: Y | X7: N | Y7: 218 E ST CHARLES RD | Z7: LOMBARD | AA7: 0 | AB7: 10764.56 | AC7: 5634.48 | AD7: =TRUE() -> TRUE
A8: =TRUE() -> TRUE | B8: =FALSE() -> FALSE | C8: 3 | D8: 3 | H8: =TRUE() -> TRUE | I8: =FALSE() -> FALSE | K8: CONSOLIDATED MANAGEMENT | L8: 06-08-121-020 | M8: 0608121020 | N8: 97423 | O8: 147698 | P8: 60 - Commercial Improvements | W8: N | X8: N | Y8: 15 E MAPLE ST | Z8: LOMBARD | AA8: 0 | AB8: 19044.68 | AC8: 20340.2 | AD8: =FALSE() -> FALSE
A9: =TRUE() -> TRUE | B9: =FALSE() -> FALSE | C9: 3 | D9: 3 | F9: fitness center | G9: 3 | H9: =FALSE() -> FALSE | I9: =TRUE() -> TRUE | K9: TRIARC DEVELOPMENT LLC | L9: 06-08-133-004 | M9: 0608133004 | N9: 28679 | O9: 99359 | P9: 60 - Commercial Improvements | Q9: 550000 | R9: 39437 | W9: N | X9: N | Y9: 216 E ST CHARLES RD | Z9: LOMBARD | AA9: 0 | AB9: 9947.92 | AC9: 5207.79 | AD9: =TRUE() -> TRUE
A10: =TRUE() -> TRUE | B10: =FALSE() -> FALSE | C10: 3 | D10: 3 | F10: dowtntown store | G10: 3 | H10: =FALSE() -> FALSE | I10: =FALSE() -> FALSE | K10: SIFLEET STACY | L10: 06-10-118-001 | M10: 0610118001 | N10: 11063 | O10: 106691 | P10: 60 - Commercial Improvements | Q10: 200000 | R10: 42647 | S10: 149500 | T10: 42647 | W10: Y | X10: N | Y10: 1 E PARK BLVD | Z10: VILLA PARK | AA10: 0 | AB10: 8899.98 | AC10: 9510.73 | AD10: =FALSE() -> FALSE
A11: =TRUE() -> TRUE | B11: =FALSE() -> FALSE | C11: 4 | D11: 4 | F11: office | G11: 3 | H11: =FALSE() -> FALSE | I11: =FALSE() -> FALSE | K11: DM EQUITIES LLC | L11: 06-19-305-006 | M11: 0619305006 | N11: 253469 | O11: 577359 | P11: 60 - Commercial Improvements | Q11: 2530000 | R11: 43413 | S11: 2640000 | T11: 43413 | W11: Y | X11: N | Y11: 555 WATERS EDGE | Z11: LOMBARD | AA11: 0 | AB11: 65128.62 | AC11: 69534.8 | AD11: =FALSE() -> FALSE
A12: =TRUE() -> TRUE | B12: =FALSE() -> FALSE | C12: 3 | D12: 3 | F12: dr office suite | G12: 4 | H12: =FALSE() -> FALSE | I12: =FALSE() -> FALSE | K12: SPK HOLDINGS LLC | L12: 06-21-405-020 | M12: 0621405020 | N12: 7819 | O12: 70367 | P12: 60 - Commercial Improvements | Q12: 235000 | R12: 42284 | W12: Y | X12: N | Y12: 1 TRANSAM PLAZA # 310 | Z12: OAKBROOK TERR | AA12: 0 | AB12: 6047.92 | AC12: 3170.04 | AD12: =TRUE() -> TRUE
A13: =TRUE() -> TRUE | B13: =FALSE() -> FALSE | C13: 3 | D13: 3 | F13: cannabis store | G13: 4 | H13: =FALSE() -> FALSE | I13: =FALSE() -> FALSE | K13: SUMMIT OBT LLC | L13: 06-22-100-008 | M13: 0622100008 | N13: 214085 | O13: 227137 | P13: 60 - Commercial Improvements | Q13: 1670000 | R13: 44958 | W13: Y | X13: N | Y13: 1S130 SUMMIT AVE | Z13: OAKBROOK TERR | AA13: 0 | AB13: 26176.36 | AC13: 27953.27 | AD13: =FALSE() -> FALSE
A14: =TRUE() -> TRUE | B14: =FALSE() -> FALSE | C14: 4 | D14: 4 | F14: office 1/2 installment | G14: 3 | H14: =FALSE() -> FALSE | I14: =FALSE() -> FALSE | K14: 1430 BRANDING DG LLC | L14: 06-30-407-009 | M14: 0630407009 | N14: 788470 | O14: 899680 | P14: 60 - Commercial Improvements | Q14: 3045000 | R14: 42551 | W14: Y | X14: Y | Y14: 1430 BRANDING AVE | Z14: DOWNERS GROVE | AA14: 0 | AB14: 96783.34 | AC14: 50579.3 | AD14: =TRUE() -> TRUE
A15: =TRUE() -> TRUE | B15: =FALSE() -> FALSE | C15: 3 | D15: 3 | F15: panera | G15: 3 | H15: =FALSE() -> FALSE | I15: =FALSE() -> FALSE | K15: PANERA LLC | L15: 07-10-105-013 | M15: 0710105013 | N15: 208880 | O15: 219486 | P15: 60 - Commercial Improvements | Q15: 2783000 | R15: 43474 | W15: N | X15: N | Y15: 1620 N ROUTE 59 | Z15: NAPERVILLE | AA15: 0 | AB15: 26738.18 | AC15: 28553.01 | AD15: =FALSE() -> FALSE
A16: =TRUE() -> TRUE | B16: =FALSE() -> FALSE | C16: 5 | D16: 5 | F16: offfice buildings | G16: 3 | H16: =FALSE() -> FALSE | I16: =FALSE() -> FALSE | K16: BOBR GROUP LLC | L16: 07-12-204-005 | M16: 0712204005 | N16: 628310 | O16: 1724338 | P16: 60 - Commercial Improvements | Q16: 10600000 | R16: 43636 | S16: 12000000 | T16: 43636 | W16: Y | X16: Y | Y16: 1717 PARK ST | Z16: NAPERVILLE | AA16: 0 | AB16: 144283.2 | AC16: 154032.31 | AD16: =FALSE() -> FALSE
A17: =TRUE() -> TRUE | B17: =FALSE() -> FALSE | C17: 3 | D17: 3 | F17: restaurant | G17: 4 | H17: =FALSE() -> FALSE | I17: =TRUE() -> TRUE | K17: 48 WEST CHICAGO LLC | L17: 07-13-436-016 | M17: 0713436016 | N17: 52963 | O17: 370507 | P17: 60 - Commercial Improvements | Q17: 1300000 | R17: 41669 | S17: 2975000 | T17: 42248 | U17: 1512000 | V17: 43224 | W17: Y | X17: Y | Y17: 36-50 W CHICAGO AVE | Z17: NAPERVILLE | AA17: 0 | AB17: 31547.26 | AC17: 33686.7 | AD17: =FALSE() -> FALSE
A18: =TRUE() -> TRUE | B18: =FALSE() -> FALSE | C18: 3 | D18: 3 | F18: white castle | G18: 4 | H18: =FALSE() -> FALSE | I18: =TRUE() -> TRUE | K18: HD WHITE CASTLE LLC | L18: 07-21-200-061 | M18: 0721200061 | N18: 123409 | O18: 141394 | P18: 60 - Commercial Improvements | Q18: 608500 | R18: 44862 | W18: Y | X18: N | Y18: 444 N RT 59 | Z18: AURORA | AA18: 0 | AB18: 20134.04 | AC18: 21503.09 | AD18: =FALSE() -> FALSE
A19: =TRUE() -> TRUE | B19: =FALSE() -> FALSE | C19: 3 | D19: 3 | H19: =TRUE() -> TRUE | I19: =FALSE() -> FALSE | K19: TF PORTFOLIO I LLC | L19: 09-04-403-001 | M19: 0904403001 | N19: 269890 | O19: 416180 | P19: 60 - Commercial Improvements | Q19: 2973333.3 | R19: 44893 | S19: 20000000 | T19: 44893 | W19: N | X19: N | Y19: 19-31 W OGDEN AVE | Z19: WESTMONT | AA19: 0 | AB19: 44589.76 | AC19: 47609.57 | AD19: =FALSE() -> FALSE
A20: =TRUE() -> TRUE | B20: =FALSE() -> FALSE | C20: 3 | D20: 3 | F20: office | G20: 4 | H20: =FALSE() -> FALSE | I20: =FALSE() -> FALSE | K20: WEST SUBURBAN BANK | L20: 09-08-116-007 | M20: 0908116007 | N20: 90733 | O20: 65758 | P20: 60 - Commercial Improvements | Q20: 300000 | R20: 43475 | S20: 412000 | T20: 43476 | W20: N | X20: N | Y20: 4925 FOREST AVE | Z20: DOWNERS GROVE | AA20: 0 | AB20: 10035.14 | AC20: 10722.51 | AD20: =FALSE() -> FALSE
A21: =TRUE() -> TRUE | B21: =FALSE() -> FALSE | C21: 3 | D21: 3 | H21: =TRUE() -> TRUE | I21: =FALSE() -> FALSE | K21: 6010 MANAGEMENT LLC | L21: 09-16-402-018 | M21: 0916402018 | N21: 200730 | O21: 163570 | P21: 60 - Commercial Improvements | Q21: 1200040 | R21: 45007 | W21: Y | X21: Y | Y21: 6010 S CASS AVE | Z21: WESTMONT | AA21: 0 | AB21: 24518.86 | AC21: 26183.88 | AD21: =FALSE() -> FALSE
A22: =TRUE() -> TRUE | B22: =FALSE() -> FALSE | C22: 3 | D22: 3 | F22: office suite | G22: 4 | H22: =FALSE() -> FALSE | I22: =FALSE() -> FALSE | K22: 6424 CASS PROPERTIES LLC | L22: 09-21-217-015 | M22: 0921217015 | N22: 22224 | O22: 41173 | P22: 60 - Commercial Improvements | Q22: 185000 | R22: 45105 | W22: Y | X22: N | Y22: 6424 S CASS AVE # 403 | Z22: WESTMONT | AA22: 0 | AB22: 4266.86 | AC22: 4564.87 | AD22: =FALSE() -> FALSE
A23: =TRUE() -> TRUE | B23: =FALSE() -> FALSE | C23: 5 | D23: 5 | F23: Hotel | G23: 5 | H23: =FALSE() -> FALSE | I23: =FALSE() -> FALSE | K23: A1 HOSPITALITY | L23: 09-26-402-028 | M23: 0926402028 | N23: 801980 | O23: 2622060 | P23: 60 - Commercial Improvements | Q23: 4080000 | R23: 41558 | S23: 8250000 | T23: 42738 | U23: 1270000 | V23: 43770 | W23: Y | X23: Y | Y23: 7800 KINGERY HWY | Z23: WILLOWBROOK | AA23: 0 | AB23: 163857.44 | AC23: 174927.81 | AD23: =FALSE() -> FALSE
A24: =TRUE() -> TRUE | B24: =FALSE() -> FALSE | C24: 3 | D24: 3 | H24: =TRUE() -> TRUE | I24: =FALSE() -> FALSE | K24: 1222 WEST ARGYLE LLC | L24: 09-30-401-130 | M24: 0930401130 | N24: 144503 | O24: 203255 | P24: 60 - Commercial Improvements | Y24: 7508 LEMONT RD | Z24: WOODRIDGE | AA24: 0 | AB24: 23103.68 | AC24: 12081.67 | AD24: =TRUE() -> TRUE
AB26: Total | AC26: =SUM(AC2:AC24) -> 1053093.8

Sheet Removed - Full Inst Under 3K
A1: Ok to Buy | B1: Do Not Buy | C1: TempBid | D1: Bid | E1: Comment | F1: 2024Comment | G1: 2024Bid | H1: 2023OkToBuy | I1: 2023DoNotBuy | J1: 2023Comment | K1: Taxpayer Name | L1: Parcel Number | M1: PINNoDashes | N1: Assessed Land | O1: Assessed Bldg | P1: ClassCode | Q1: SaleAmt | R1: SaleDt | S1: MortAmt | T1: MortDt | U1: 2ndMort | V1: 2ndMortDt | W1: Lien | X1: Judgmt | Y1: Property Address 1 | Z1: Property City | AA1: Back Tax | AB1: TotalTaxBilled | AC1: Judgment Amount | AD1: HalfInstallment
A2: =TRUE() -> TRUE | B2: =FALSE() -> FALSE | C2: 3 | H2: =FALSE() -> FALSE | I2: =FALSE() -> FALSE | K2: ESQUIVEL ALEJANDRO GUZMAN | L2: 01-03-304-022 | M2: 0103304022 | N2: 33518 | O2: 81804 | P2: 40 - Residential Improvements | Q2: 346000 | R2: 45322 | S2: 356500 | T2: 45600 | W2: N | X2: N | Y2: 914 BRYN MAWR AVE | Z2: BARTLETT | AA2: 0 | AB2: 142.96 | AC2: 162.61 | AD2: =FALSE() -> FALSE
A3: =TRUE() -> TRUE | B3: =FALSE() -> FALSE | C3: 2 | H3: =FALSE() -> FALSE | I3: =FALSE() -> FALSE | K3: MAYNARD DAVID | L3: 02-03-323-003 | M3: 0203323003 | N3: 6780 | O3: 31362 | P3: 40 - Residential Improvements | R3: 40214 | W3: N | X3: Y | Y3: 77 W CENTRAL AVE # 105 | Z3: ROSELLE | AA3: 0 | AB3: 2265.08 | AC3: 2427.97 | AD3: =FALSE() -> FALSE
A4: =TRUE() -> TRUE | B4: =FALSE() -> FALSE | C4: 2 | H4: =FALSE() -> FALSE | I4: =FALSE() -> FALSE | K4: KEAR DANIEL & FELICIDAD | L4: 02-22-112-081 | M4: 0222112081 | N4: 5369 | O4: 36031 | P4: 40 - Residential Improvements | Q4: 130000 | R4: 45526 | W4: N | X4: N | Y4: 152 W DUNTEMAN DR # 201 | Z4: GLENDALE HTS | AA4: 0 | AB4: 2339.48 | AC4: 2507.4 | AD4: =FALSE() -> FALSE
A5: =TRUE() -> TRUE | B5: =FALSE() -> FALSE | C5: 2 | H5: =FALSE() -> FALSE | I5: =FALSE() -> FALSE | K5: SANDERS LOIS P | L5: 02-22-113-100 | M5: 0222113100 | N5: 5369 | O5: 39104 | P5: 40 - Residential Improvements | Q5: 129000 | R5: 38162 | W5: N | X5: N | Y5: 200 S WATERS EDGE DR # 202 | Z5: GLENDALE HTS | AA5: 0 | AB5: 2622.52 | AC5: 2809.54 | AD5: =FALSE() -> FALSE
A6: =TRUE() -> TRUE | B6: =FALSE() -> FALSE | C6: 2 | H6: =FALSE() -> FALSE | I6: =FALSE() -> FALSE | K6: ST ANDREW UKRAINIAN CHURCH | L6: 02-23-418-004 | M6: 0223418004 | N6: 5861 | O6: 26299 | P6: 40 - Residential Improvements | R6: 36985 | W6: N | X6: N | Y6: 300 E ARMY TRAIL RD # 15 | Z6: BLOOMINGDALE | AA6: 0 | AB6: 2168.7 | AC6: 2325.09 | AD6: =FALSE() -> FALSE
A7: =TRUE() -> TRUE | B7: =FALSE() -> FALSE | C7: 2 | H7: =FALSE() -> FALSE | I7: =FALSE() -> FALSE | K7: ST ANDREW UKRANIAN CHURCH | L7: 02-23-418-008 | M7: 0223418008 | N7: 5861 | O7: 29021 | P7: 40 - Residential Improvements | R7: 36985 | W7: N | X7: N | Y7: 300 E ARMY TRAIL RD # 19 | Z7: BLOOMINGDALE | AA7: 0 | AB7: 2413.04 | AC7: 2585.92 | AD7: =FALSE() -> FALSE
A8: =TRUE() -> TRUE | B8: =FALSE() -> FALSE | C8: 3 | H8: =FALSE() -> FALSE | I8: =FALSE() -> FALSE | K8: AIARDO L & R KIRBY | L8: 02-24-207-008 | M8: 0224207008 | N8: 5500 | O8: 35134 | P8: 40 - Residential Improvements | Q8: 21000 | R8: 41002 | S8: 6000 | T8: 41002 | W8: N | X8: Y | Y8: 941 N RT 53 # 101C | Z8: ADDISON | AA8: 0 | AB8: 1727.18 | AC8: 1853.76 | AD8: =FALSE() -> FALSE
A9: =TRUE() -> TRUE | B9: =FALSE() -> FALSE | C9: 3 | H9: =FALSE() -> FALSE | I9: =FALSE() -> FALSE | K9: ABBAS NAJAM & SYEDA KAZMI | L9: 02-29-111-090 | M9: 0229111090 | N9: 9492 | O9: 28475 | P9: 40 - Residential Improvements | Q9: 186000 | R9: 45768 | S9: 139500 | T9: 45768 | W9: N | X9: N | Y9: 105 W ELK TRL # 305 | Z9: CAROL STREAM | AA9: 0 | AB9: 2570.88 | AC9: 2754.41 | AD9: =FALSE() -> FALSE
A10: =TRUE() -> TRUE | B10: =FALSE() -> FALSE | C10: 3 | H10: =FALSE() -> FALSE | I10: =FALSE() -> FALSE | K10: PATEL ARPAN | L10: 02-29-111-123 | M10: 0229111123 | N10: 9492 | O10: 13249 | P10: 40 - Residential Improvements | Q10: 172000 | R10: 45754 | S10: 154800 | T10: 45754 | W10: N | X10: N | Y10: 161 ELK TRL # 262 | Z10: CAROL STREAM | AA10: 0 | AB10: 1264.64 | AC10: 1360 | AD10: =FALSE() -> FALSE
A11: =TRUE() -> TRUE | B11: =FALSE() -> FALSE | C11: 3 | H11: =FALSE() -> FALSE | I11: =FALSE() -> FALSE | K11: THOMAS III JOHN | L11: 02-29-117-009 | M11: 0229117009 | N11: 8562 | O11: 34467 | P11: 40 - Residential Improvements | Q11: 181000 | R11: 45414 | S11: 183750 | T11: 45700 | W11: N | X11: N | Y11: 122 KLEIN CREEK CT # 3C | Z11: CAROL STREAM | AA11: 0 | AB11: 534.04 | AC11: 580.09 | AD11: =FALSE() -> FALSE
A12: =TRUE() -> TRUE | B12: =FALSE() -> FALSE | C12: 3 | H12: =FALSE() -> FALSE | I12: =FALSE() -> FALSE | K12: GNATOVYCH VOLODYMYR | L12: 02-33-204-172 | M12: 0233204172 | N12: 12105 | O12: 26000 | P12: 40 - Residential Improvements | Q12: 335000 | R12: 45562 | S12: 288000 | T12: 45562 | W12: N | X12: N | Y12: 1419 CLUB DR # A | Z12: GLENDALE HTS | AA12: 0 | AB12: 2022.42 | AC12: 2168.93 | AD12: =FALSE() -> FALSE
A13: =TRUE() -> TRUE | B13: =FALSE() -> FALSE | C13: 2 | H13: =FALSE() -> FALSE | I13: =FALSE() -> FALSE | K13: LUKASIK MITCHELL & D H | L13: 03-20-412-010 | M13: 0320412010 | N13: 41141 | O13: 59383 | P13: 40 - Residential Improvements | W13: N | X13: N | Y13: 701 CRAIG PL | Z13: ADDISON | AA13: 0 | AB13: 1700.7 | AC13: 1825.5 | AD13: =FALSE() -> FALSE
A14: =TRUE() -> TRUE | B14: =FALSE() -> FALSE | C14: 2 | G14: 2 | H14: =FALSE() -> FALSE | I14: =FALSE() -> FALSE | K14: RUFFIN TERRY K | L14: 03-24-314-006 | M14: 0324314006 | N14: 5265 | O14: 33602 | P14: 40 - Residential Improvements | Q14: 85000 | R14: 44482 | W14: N | X14: Y | Y14: 310 GEORGE ST # 2SE | Z14: BENSENVILLE | AA14: 0 | AB14: 2683.82 | AC14: 2874.98 | AD14: =FALSE() -> FALSE
A15: =TRUE() -> TRUE | B15: =FALSE() -> FALSE | C15: 2 | H15: =FALSE() -> FALSE | I15: =FALSE() -> FALSE | K15: VILLASENOR MIGUEL ANGEL | L15: 03-25-120-036 | M15: 0325120036 | N15: 5994 | O15: 23953 | P15: 40 - Residential Improvements | Q15: 139000 | R15: 45768 | W15: N | X15: N | Y15: 1043 S YORK RD # 412 | Z15: BENSENVILLE | AA15: 0 | AB15: 2183.92 | AC15: 2341.34 | AD15: =FALSE() -> FALSE
A16: =TRUE() -> TRUE | B16: =FALSE() -> FALSE | C16: 3 | G16: 2 | H16: =TRUE() -> TRUE | I16: =FALSE() -> FALSE | K16: MANCZKO THADDEUS J | L16: 03-28-315-008 | M16: 0328315008 | N16: 43240 | O16: 64844 | P16: 40 - Residential Improvements | R16: 34655 | S16: 275000 | T16: 38579 | W16: N | X16: Y | Y16: 239 S HALE ST | Z16: ADDISON | AA16: 0 | AB16: 2853.78 | AC16: 2992.2 | AD16: =FALSE() -> FALSE
A17: =TRUE() -> TRUE | B17: =FALSE() -> FALSE | C17: 2 | H17: =FALSE() -> FALSE | I17: =FALSE() -> FALSE | K17: MERKO GRISELDA | L17: 03-28-318-056 | M17: 0328318056 | N17: 3209 | O17: 28914 | P17: 40 - Residential Improvements | Q17: 101000 | R17: 45559 | W17: N | X17: N | Y17: 300 W FULLERTON AVE # 227 | Z17: ADDISON | AA17: 0 | AB17: 2264.08 | AC17: 2426.9 | AD17: =FALSE() -> FALSE
A18: =TRUE() -> TRUE | B18: =FALSE() -> FALSE | C18: 2 | H18: =FALSE() -> FALSE | I18: =FALSE() -> FALSE | K18: ESTATE ASSET GROUP LLC | L18: 03-28-400-014 | M18: 0328400014 | N18: 42250 | O18: 43294 | P18: 40 - Residential Improvements | Q18: 116000 | R18: 45686 | W18: N | X18: N | Y18: 8 S IOWA AVE | Z18: ADDISON | AA18: 0 | AB18: 1966.42 | AC18: 2109.15 | AD18: =FALSE() -> FALSE
A19: =TRUE() -> TRUE | B19: =FALSE() -> FALSE | C19: 2 | H19: =FALSE() -> FALSE | I19: =FALSE() -> FALSE | K19: GUDMUNDSON ERIC A | L19: 03-29-213-031 | M19: 0329213031 | N19: 4591 | O19: 42098 | P19: 40 - Residential Improvements | Q19: 91000 | R19: 37166 | W19: N | X19: N | Y19: 235 N MILL RD # 216B | Z19: ADDISON | AA19: 0 | AB19: 2726.84 | AC19: 2920.9 | AD19: =FALSE() -> FALSE
A20: =TRUE() -> TRUE | B20: =FALSE() -> FALSE | C20: 2 | H20: =TRUE() -> TRUE | I20: =FALSE() -> FALSE | K20: BARI SAQIB I | L20: 05-03-211-182 | M20: 0503211182 | N20: 3107 | O20: 29441 | P20: 40 - Residential Improvements | Q20: 131000 | R20: 45597 | W20: N | X20: N | Y20: 1129 CEDAR ST # 1B | Z20: GLENDALE HTS | AA20: 0 | AB20: 2724.52 | AC20: 2918.42 | AD20: =FALSE() -> FALSE
A21: =TRUE() -> TRUE | B21: =FALSE() -> FALSE | C21: 2 | H21: =FALSE() -> FALSE | I21: =FALSE() -> FALSE | K21: YAKOOB MUHAMMAD & AFIFAH | L21: 05-23-321-194 | M21: 0523321194 | N21: 5399 | O21: 34135 | P21: 40 - Residential Improvements | Q21: 155500 | R21: 45719 | W21: N | X21: Y | Y21: 461 RAINTREE CT # 1-D | Z21: GLEN ELLYN | AA21: 0 | AB21: 2332.16 | AC21: 2499.58 | AD21: =FALSE() -> FALSE
A22: =TRUE() -> TRUE | B22: =FALSE() -> FALSE | C22: 2 | H22: =FALSE() -> FALSE | I22: =FALSE() -> FALSE | K22: YOUNG TR ROSEMARY | L22: 05-27-106-095 | M22: 0527106095 | N22: 6920 | O22: 56438 | P22: 40 - Residential Improvements | W22: N | X22: N | Y22: 1661 VALLEY FORGE CT # D | Z22: WHEATON | AA22: 0 | AB22: 1231.68 | AC22: 1324.82 | AD22: =FALSE() -> FALSE
A23: =TRUE() -> TRUE | B23: =FALSE() -> FALSE | C23: 2 | H23: =FALSE() -> FALSE | I23: =FALSE() -> FALSE | K23: TUREK ROSE MARIE | L23: 06-02-322-059 | M23: 0602322059 | N23: 3287 | O23: 29533 | P23: 40 - Residential Improvements | Q23: 62000 | R23: 40690 | W23: N | X23: Y | Y23: 255 S WEST AVE | Z23: ELMHURST | AA23: 0 | AB23: 1013.66 | AC23: 1092.08 | AD23: =FALSE() -> FALSE
A24: =TRUE() -> TRUE | B24: =FALSE() -> FALSE | C24: 2 | H24: =FALSE() -> FALSE | I24: =FALSE() -> FALSE | K24: JONES JAMES D | L24: 06-02-322-065 | M24: 0602322065 | N24: 2585 | O24: 23174 | P24: 40 - Residential Improvements | Q24: 58000 | R24: 42200 | W24: N | X24: N | Y24: 255 S WEST AVE # 402 | Z24: ELMHURST | AA24: 0 | AB24: 1070.26 | AC24: 1152.5 | AD24: =FALSE() -> FALSE
A25: =TRUE() -> TRUE | B25: =FALSE() -> FALSE | C25: 2 | H25: =FALSE() -> FALSE | I25: =FALSE() -> FALSE | K25: NURAIN SABA & SUMERA FATIMA | L25: 06-04-418-007 | M25: 0604418007 | N25: 3536 | O25: 31761 | P25: 40 - Residential Improvements | Q25: 54000 | R25: 41900 | W25: Y | X25: N | Y25: 323 N PRINCETON AVE # 7 | Z25: VILLA PARK | AA25: 0 | AB25: 2667.8 | AC25: 2857.88 | AD25: =FALSE() -> FALSE
A26: =TRUE() -> TRUE | B26: =FALSE() -> FALSE | C26: 2 | H26: =FALSE() -> FALSE | I26: =FALSE() -> FALSE | K26: AUGUST RICHARD | L26: 06-19-203-054 | M26: 0619203054 | N26: 3006 | O26: 27067 | P26: 40 - Residential Improvements | R26: 43725 | W26: N | X26: Y | Y26: 1320A LORE LN # 106 | Z26: LOMBARD | AA26: 0 | AB26: 938.02 | AC26: 1011.34 | AD26: =FALSE() -> FALSE
A27: =TRUE() -> TRUE | B27: =FALSE() -> FALSE | C27: 3 | H27: =FALSE() -> FALSE | I27: =FALSE() -> FALSE | K27: SENS JACOB O | L27: 06-19-212-046 | M27: 0619212046 | N27: 3817 | O27: 34356 | P27: 40 - Residential Improvements | Q27: 130000 | R27: 45408 | S27: 104000 | T27: 45408 | W27: N | X27: N | Y27: 1301 S FINLEY RD # 306 | Z27: LOMBARD | AA27: 0 | AB27: 1722.74 | AC27: 1849.02 | AD27: =FALSE() -> FALSE
A28: =TRUE() -> TRUE | B28: =FALSE() -> FALSE | C28: 3 | G28: 2 | H28: =FALSE() -> FALSE | I28: =FALSE() -> FALSE | K28: BENNETT RUBY & SAMMUEL | L28: 06-19-212-079 | M28: 0619212079 | N28: 4672 | O28: 42045 | P28: 40 - Residential Improvements | Q28: 107000 | R28: 37292 | S28: 244500 | T28: 39346 | W28: N | X28: Y | Y28: 1301 S FINLEY RD # 417 | Z28: LOMBARD | AA28: 0 | AB28: 2386.58 | AC28: 2557.68 | AD28: =FALSE() -> FALSE
A29: =TRUE() -> TRUE | B29: =FALSE() -> FALSE | C29: 2 | H29: =FALSE() -> FALSE | I29: =FALSE() -> FALSE | K29: RIENDEAU CHRISTINE | L29: 06-19-213-010 | M29: 0619213010 | N29: 3817 | O29: 34356 | P29: 40 - Residential Improvements | Q29: 67000 | R29: 36497 | W29: N | X29: Y | Y29: 1311 S FINLEY RD # 110 | Z29: LOMBARD | AA29: 0 | AB29: 1499.5 | AC29: 1576.98 | AD29: =FALSE() -> FALSE
A30: =TRUE() -> TRUE | B30: =FALSE() -> FALSE | C30: 2 | H30: =FALSE() -> FALSE | I30: =FALSE() -> FALSE | K30: SYED SAJID | L30: 06-19-214-013 | M30: 0619214013 | N30: 4747 | O30: 42715 | P30: 40 - Residential Improvements | Q30: 180000 | R30: 45413 | W30: N | X30: N | Y30: 1321 S FINLEY RD # 113 | Z30: LOMBARD | AA30: 0 | AB30: 2444.46 | AC30: 2619.46 | AD30: =FALSE() -> FALSE
A31: =TRUE() -> TRUE | B31: =FALSE() -> FALSE | C31: 2 | H31: =FALSE() -> FALSE | I31: =FALSE() -> FALSE | K31: RISTINE MYRNA B | L31: 06-20-207-037 | M31: 0620207037 | N31: 4207 | O31: 38000 | P31: 40 - Residential Improvements | R31: 35759 | W31: Y | X31: Y | Y31: 1406 S FAIRFIELD AVE # 37A | Z31: LOMBARD | AA31: 0 | AB31: 2657.72 | AC31: 2847.12 | AD31: =FALSE() -> FALSE
A32: =TRUE() -> TRUE | B32: =FALSE() -> FALSE | C32: 3 | H32: =FALSE() -> FALSE | I32: =FALSE() -> FALSE | K32: ROSS KAREN J | L32: 06-21-211-039 | M32: 0621211039 | N32: 6240 | O32: 56211 | P32: 40 - Residential Improvements | S32: 35820 | T32: 38023 | W32: Y | X32: Y | Y32: 18W055 STANDISH LN | Z32: VILLA PARK | AA32: 0 | AB32: 340.08 | AC32: 373.03 | AD32: =FALSE() -> FALSE
A33: =TRUE() -> TRUE | B33: =FALSE() -> FALSE | C33: 2 | H33: =FALSE() -> FALSE | I33: =FALSE() -> FALSE | K33: SELBY LAURA G | L33: 06-21-211-081 | M33: 0621211081 | N33: 4250 | O33: 38217 | P33: 40 - Residential Improvements | R33: 37473 | W33: N | X33: N | Y33: 1S265 DILLON LN | Z33: VILLA PARK | AA33: 0 | AB33: 2548.1 | AC33: 2730.09 | AD33: =FALSE() -> FALSE
A34: =TRUE() -> TRUE | B34: =FALSE() -> FALSE | C34: 2 | H34: =TRUE() -> TRUE | I34: =FALSE() -> FALSE | K34: WET N BLUE INC | L34: 06-28-107-103 | M34: 0628107103 | N34: 4477 | O34: 40304 | P34: 40 - Residential Improvements | Q34: 128000 | R34: 44879 | W34: N | X34: Y | Y34: 40 N TOWER RD # 1-E | Z34: OAK BROOK | AA34: 0 | AB34: 2729.86 | AC34: 2924.12 | AD34: =FALSE() -> FALSE
A35: =TRUE() -> TRUE | B35: =FALSE() -> FALSE | C35: 3 | G35: 2 | H35: =FALSE() -> FALSE | I35: =FALSE() -> FALSE | K35: BREMER DAVID | L35: 06-28-107-206 | M35: 0628107206 | N35: 4801 | O35: 43202 | P35: 40 - Residential Improvements | Q35: 113500 | R35: 37706 | S35: 90000 | T35: 37785 | W35: N | X35: Y | Y35: 20 N TOWER RD # 10H | Z35: OAK BROOK | AA35: 0 | AB35: 2375.22 | AC35: 2545.54 | AD35: =FALSE() -> FALSE
A36: =TRUE() -> TRUE | B36: =FALSE() -> FALSE | C36: 2 | H36: =FALSE() -> FALSE | I36: =FALSE() -> FALSE | K36: DAWSON MICHAEL C | L36: 06-28-107-276 | M36: 0628107276 | N36: 4477 | O36: 40304 | P36: 40 - Residential Improvements | Q36: 74500 | R36: 35020 | W36: N | X36: Y | Y36: 20 N TOWER RD # 1-L-W | Z36: OAK BROOK | AA36: 0 | AB36: 2729.86 | AC36: 2924.12 | AD36: =FALSE() -> FALSE
A37: =TRUE() -> TRUE | B37: =FALSE() -> FALSE | C37: 2 | H37: =FALSE() -> FALSE | I37: =FALSE() -> FALSE | K37: PRATT MINA M | L37: 07-09-206-040 | M37: 0709206040 | N37: 46375 | O37: 56847 | P37: 40 - Residential Improvements | W37: N | X37: N | Y37: 30W162 CLAYMORE LN | Z37: NAPERVILLE | AA37: 0 | AB37: 1405.7 | AC37: 1510.59 | AD37: =FALSE() -> FALSE
A38: =TRUE() -> TRUE | B38: =FALSE() -> FALSE | C38: 2 | H38: =FALSE() -> FALSE | I38: =FALSE() -> FALSE | K38: TAGLIAPIETRA RONALD | L38: 07-12-426-011 | M38: 0712426011 | N38: 5787 | O38: 44783 | P38: 40 - Residential Improvements | Q38: 222000 | R38: 45496 | W38: N | X38: N | Y38: 520 BURNING TREE LN # 112 | Z38: NAPERVILLE | AA38: 0 | AB38: 2610.74 | AC38: 2796.96 | AD38: =FALSE() -> FALSE
A39: =TRUE() -> TRUE | B39: =FALSE() -> FALSE | C39: 2 | H39: =FALSE() -> FALSE | I39: =FALSE() -> FALSE | K39: CAMPBELL RAYMOND C | L39: 07-12-426-094 | M39: 0712426094 | N39: 4741 | O39: 36815 | P39: 40 - Residential Improvements | Q39: 60000 | R39: 41186 | W39: N | X39: N | Y39: 1041 N MILL ST # 103 | Z39: NAPERVILLE | AA39: 0 | AB39: 2057.94 | AC39: 2206.85 | AD39: =FALSE() -> FALSE
A40: =TRUE() -> TRUE | B40: =FALSE() -> FALSE | C40: 2 | H40: =FALSE() -> FALSE | I40: =FALSE() -> FALSE | K40: GARBACZ JACK | L40: 07-12-426-169 | M40: 0712426169 | N40: 4830 | O40: 36114 | P40: 40 - Residential Improvements | Q40: 96000 | R40: 37629 | W40: N | X40: N | Y40: 1060 MILL ST # 1-203 | Z40: NAPERVILLE | AA40: 0 | AB40: 1529.78 | AC40: 1643.04 | AD40: =FALSE() -> FALSE
...
