Workbook

Sheet Sale List
A1: Kendall County - Final Sale List 2025 (Real Estate)
A2: Source: 2026_Sale_2025_Taxes_All_Buys_All_Buyers.pdf, report dated Monday, October 26, 2026
A4: Certificate | B4: Parcel ID | C4: Assessee Name | D4: Amount | E4: Buyer # | F4: Buyer Name | G4: Bid %
A5: 2026-00001 | B5: 01-03-100-005 | C5: VARGAS, TEODORO & THE | D5: 6573.36 | E5: 112 | F5: PRIVATE EQUITY GROUP | G5: 5
A6: 2026-00002 | B6: 01-06-100-015 | C6: CTI TOWERS ASSETS II LL | D6: 3484.11 | E6: 253 | F6: RAVEN SECURITIES INC | G6: 5
A7: 2026-00003 | B7: 01-12-200-004 | C7: ELDAMAIN ROAD FARM C E | D7: 5347.79 | E7: 253 | F7: RAVEN SECURITIES INC | G7: 4
A8: 2026-00004 | B8: 01-16-455-032 | C8: TREVINO, JOSE G & SILVIA | D8: 10926.14 | E8: 253 | F8: RAVEN SECURITIES INC | G8: 4
A9: 2026-00005 | B9: 01-21-201-027 | C9: DUNLAP, BENJAMIN M & PE | D9: 4991.75 | E9: 253 | F9: RAVEN SECURITIES INC | G9: 4
A10: 2026-00006 | B10: 01-22-176-007 | C10: ROCHA, JOSE LUIS & ARMI | D10: 5885.18 | E10: 253 | F10: RAVEN SECURITIES INC | G10: 4
A11: 2026-00007 | B11: 01-22-183-003 | C11: WOLLENWEBER, DAVID A J | D11: 1919.77 | E11: 136 | F11: AUCTION Z-2 INC | G11: 4
A12: 2026-00008 | B12: 01-22-204-001 | C12: PEREZ, MIGUEL A | D12: 5109.21 | E12: 136 | F12: AUCTION Z-2 INC | G12: 4
A13: 2026-00009 | B13: 01-22-229-020 | C13: SCHIMANDLE, JUSTIN W & , | D13: 7411.43 | E13: 253 | F13: RAVEN SECURITIES INC | G13: 4
A14: 2026-00010 | B14: 01-22-277-012 | C14: QUINTERO, MIGUEL H & SO | D14: 2683.48 | E14: 136 | F14: AUCTION Z-2 INC | G14: 4
A15: 2026-00011 | B15: 01-22-282-015 | C15: YOUNG THOMAS R &, OSU | D15: 1154.92 | E15: 139 | F15: CARNIOLA CAPITAL LLC | G15: 8
A16: 2026-00012 | B16: 01-22-331-007 | C16: HILL BONNIE L &, HILL DEB | D16: 2707.17 | E16: 136 | F16: AUCTION Z-2 INC | G16: 4
... A421: 2026-00417 | B421: 09-34-200-003 | C421: JWS LAND COMPANY LLC, | D421: 1526.77 | E421: 139 | F421: CARNIOLA CAPITAL LLC | G421: 7
A422: =COUNTA(A5:A421)&" certificates" -> 417 certificates | C422: TOTAL | D422: =SUM(D5:D421) -> 2291638

Sheet Totals by Bidder
A1: Totals by Bidder
A3: Buyer # | B3: Buyer Name | C3: # Certificates | D3: Total Amount | E3: % of Total $ | F3: Wtd Avg Bid % | G3: Min Bid % | H3: Max Bid %
A4: 112 | B4: PRIVATE EQUITY GROUP | C4: =COUNTIF('Sale List'!$F$5:$F$421,B4) -> 146 | D4: =SUMIFS('Sale List'!$D$5:$D$421,'Sale List'!$F$5:$F$421,B4) -> 1138654.9 | E4: =D4/$D$14 -> 0.49687379 | F4: =SUMPRODUCT(('Sale List'!$F$5:$F$421=B4)*'Sale List'!$D$5:$D$421*'Sale List'!$G$5:$G$421)/D4 -> 4.9469335 | G4: =_xlfn.MINIFS('Sale List'!$G$5:$G$421,'Sale List'!$F$5:$F$421,B4) -> 4 | H4: =_xlfn.MAXIFS('Sale List'!$G$5:$G$421,'Sale List'!$F$5:$F$421,B4) -> 6
A5: 235 | B5: 1095 INVESTMENTS LLC | C5: =COUNTIF('Sale List'!$F$5:$F$421,B5) -> 48 | D5: =SUMIFS('Sale List'!$D$5:$D$421,'Sale List'!$F$5:$F$421,B5) -> 459498.7 | E5: =D5/$D$14 -> 0.20051103 | F5: =SUMPRODUCT(('Sale List'!$F$5:$F$421=B5)*'Sale List'!$D$5:$D$421*'Sale List'!$G$5:$G$421)/D5 -> 5.0357449 | G5: =_xlfn.MINIFS('Sale List'!$G$5:$G$421,'Sale List'!$F$5:$F$421,B5) -> 5 | H5: =_xlfn.MAXIFS('Sale List'!$G$5:$G$421,'Sale List'!$F$5:$F$421,B5) -> 6
A6: 253 | B6: RAVEN SECURITIES INC | C6: =COUNTIF('Sale List'!$F$5:$F$421,B6) -> 48 | D6: =SUMIFS('Sale List'!$D$5:$D$421,'Sale List'!$F$5:$F$421,B6) -> 299894.79 | E6: =D6/$D$14 -> 0.13086482 | F6: =SUMPRODUCT(('Sale List'!$F$5:$F$421=B6)*'Sale List'!$D$5:$D$421*'Sale List'!$G$5:$G$421)/D6 -> 4.1218964 | G6: =_xlfn.MINIFS('Sale List'!$G$5:$G$421,'Sale List'!$F$5:$F$421,B6) -> 4 | H6: =_xlfn.MAXIFS('Sale List'!$G$5:$G$421,'Sale List'!$F$5:$F$421,B6) -> 7
A7: 136 | B7: AUCTION Z-2 INC | C7: =COUNTIF('Sale List'!$F$5:$F$421,B7) -> 53 | D7: =SUMIFS('Sale List'!$D$5:$D$421,'Sale List'!$F$5:$F$421,B7) -> 249850.64 | E7: =D7/$D$14 -> 0.1090271 | F7: =SUMPRODUCT(('Sale List'!$F$5:$F$421=B7)*'Sale List'!$D$5:$D$421*'Sale List'!$G$5:$G$421)/D7 -> 4.2024373 | G7: =_xlfn.MINIFS('Sale List'!$G$5:$G$421,'Sale List'!$F$5:$F$421,B7) -> 4 | H7: =_xlfn.MAXIFS('Sale List'!$G$5:$G$421,'Sale List'!$F$5:$F$421,B7) -> 5
A8: 139 | B8: CARNIOLA CAPITAL LLC | C8: =COUNTIF('Sale List'!$F$5:$F$421,B8) -> 62 | D8: =SUMIFS('Sale List'!$D$5:$D$421,'Sale List'!$F$5:$F$421,B8) -> 84426.33 | E8: =D8/$D$14 -> 0.036841041 | F8: =SUMPRODUCT(('Sale List'!$F$5:$F$421=B8)*'Sale List'!$D$5:$D$421*'Sale List'!$G$5:$G$421)/D8 -> 7.7318217 | G8: =_xlfn.MINIFS('Sale List'!$G$5:$G$421,'Sale List'!$F$5:$F$421,B8) -> 7 | H8: =_xlfn.MAXIFS('Sale List'!$G$5:$G$421,'Sale List'!$F$5:$F$421,B8) -> 9
A9: 254 | B9: BERNICE LLC | C9: =COUNTIF('Sale List'!$F$5:$F$421,B9) -> 21 | D9: =SUMIFS('Sale List'!$D$5:$D$421,'Sale List'!$F$5:$F$421,B9) -> 20049.26 | E9: =D9/$D$14 -> 0.0087488774 | F9: =SUMPRODUCT(('Sale List'!$F$5:$F$421=B9)*'Sale List'!$D$5:$D$421*'Sale List'!$G$5:$G$421)/D9 -> 0.62015655 | G9: =_xlfn.MINIFS('Sale List'!$G$5:$G$421,'Sale List'!$F$5:$F$421,B9) -> 0 | H9: =_xlfn.MAXIFS('Sale List'!$G$5:$G$421,'Sale List'!$F$5:$F$421,B9) -> 1
A10: 006 | B10: BYDSOM INC | C10: =COUNTIF('Sale List'!$F$5:$F$421,B10) -> 12 | D10: =SUMIFS('Sale List'!$D$5:$D$421,'Sale List'!$F$5:$F$421,B10) -> 15596.99 | E10: =D10/$D$14 -> 0.0068060444 | F10: =SUMPRODUCT(('Sale List'!$F$5:$F$421=B10)*'Sale List'!$D$5:$D$421*'Sale List'!$G$5:$G$421)/D10 -> 9 | G10: =_xlfn.MINIFS('Sale List'!$G$5:$G$421,'Sale List'!$F$5:$F$421,B10) -> 9 | H10: =_xlfn.MAXIFS('Sale List'!$G$5:$G$421,'Sale List'!$F$5:$F$421,B10) -> 9
A11: 241 | B11: AMERICAN TAX LIEN LLC | C11: =COUNTIF('Sale List'!$F$5:$F$421,B11) -> 6 | D11: =SUMIFS('Sale List'!$D$5:$D$421,'Sale List'!$F$5:$F$421,B11) -> 12517.08 | E11: =D11/$D$14 -> 0.0054620668 | F11: =SUMPRODUCT(('Sale List'!$F$5:$F$421=B11)*'Sale List'!$D$5:$D$421*'Sale List'!$G$5:$G$421)/D11 -> 7.9191273 | G11: =_xlfn.MINIFS('Sale List'!$G$5:$G$421,'Sale List'!$F$5:$F$421,B11) -> 7 | H11: =_xlfn.MAXIFS('Sale List'!$G$5:$G$421,'Sale List'!$F$5:$F$421,B11) -> 9
A12: 029 | B12: TAX LIEN INVESTMENTS | C12: =COUNTIF('Sale List'!$F$5:$F$421,B12) -> 5 | D12: =SUMIFS('Sale List'!$D$5:$D$421,'Sale List'!$F$5:$F$421,B12) -> 6019.47 | E12: =D12/$D$14 -> 0.0026267107 | F12: =SUMPRODUCT(('Sale List'!$F$5:$F$421=B12)*'Sale List'!$D$5:$D$421*'Sale List'!$G$5:$G$421)/D12 -> 4 | G12: =_xlfn.MINIFS('Sale List'!$G$5:$G$421,'Sale List'!$F$5:$F$421,B12) -> 4 | H12: =_xlfn.MAXIFS('Sale List'!$G$5:$G$421,'Sale List'!$F$5:$F$421,B12) -> 4
A13: 079 | B13: BIG GROVE INVESTMENT | C13: =COUNTIF('Sale List'!$F$5:$F$421,B13) -> 16 | D13: =SUMIFS('Sale List'!$D$5:$D$421,'Sale List'!$F$5:$F$421,B13) -> 5129.88 | E13: =D13/$D$14 -> 0.0022385211 | F13: =SUMPRODUCT(('Sale List'!$F$5:$F$421=B13)*'Sale List'!$D$5:$D$421*'Sale List'!$G$5:$G$421)/D13 -> 5.1996207 | G13: =_xlfn.MINIFS('Sale List'!$G$5:$G$421,'Sale List'!$F$5:$F$421,B13) -> 3 | H13: =_xlfn.MAXIFS('Sale List'!$G$5:$G$421,'Sale List'!$F$5:$F$421,B13) -> 9
B14: TOTAL | C14: =SUM(C4:C13) -> 417 | D14: =SUM(D4:D13) -> 2291638 | E14: =SUM(E4:E13) -> 1 | F14: =SUMPRODUCT('Sale List'!$D$5:$D$421,'Sale List'!$G$5:$G$421)/D14 -> 4.8822443 | G14: =MIN('Sale List'!$G$5:$G$421) -> 0 | H14: =MAX('Sale List'!$G$5:$G$421) -> 9
A16: Wtd Avg Bid % = average bid rate weighted by certificate amount.

Sheet Totals by Bidder & Rate
A1: Totals by Bidder and Bid Rate
A3: Buyer # | B3: Buyer Name | C3: Bid % | D3: # Certificates | E3: Total Amount
A4: 112 | B4: PRIVATE EQUITY GROUP | C4: 4 | D4: =COUNTIFS('Sale List'!$F$5:$F$421,B4,'Sale List'!$G$5:$G$421,C4) -> 9 | E4: =SUMIFS('Sale List'!$D$5:$D$421,'Sale List'!$F$5:$F$421,B4,'Sale List'!$G$5:$G$421,C4) -> 112371.05
A5: 112 | B5: PRIVATE EQUITY GROUP | C5: 5 | D5: =COUNTIFS('Sale List'!$F$5:$F$421,B5,'Sale List'!$G$5:$G$421,C5) -> 130 | E5: =SUMIFS('Sale List'!$D$5:$D$421,'Sale List'!$F$5:$F$421,B5,'Sale List'!$G$5:$G$421,C5) -> 974337.24
A6: 112 | B6: PRIVATE EQUITY GROUP | C6: 6 | D6: =COUNTIFS('Sale List'!$F$5:$F$421,B6,'Sale List'!$G$5:$G$421,C6) -> 7 | E6: =SUMIFS('Sale List'!$D$5:$D$421,'Sale List'!$F$5:$F$421,B6,'Sale List'!$G$5:$G$421,C6) -> 51946.58
B7: PRIVATE EQUITY GROUP Subtotal | D7: =SUM(D4:D6) -> 146 | E7: =SUM(E4:E6) -> 1138654.9
A8: 235 | B8: 1095 INVESTMENTS LLC | C8: 5 | D8: =COUNTIFS('Sale List'!$F$5:$F$421,B8,'Sale List'!$G$5:$G$421,C8) -> 45 | E8: =SUMIFS('Sale List'!$D$5:$D$421,'Sale List'!$F$5:$F$421,B8,'Sale List'!$G$5:$G$421,C8) -> 443073.98
A9: 235 | B9: 1095 INVESTMENTS LLC | C9: 6 | D9: =COUNTIFS('Sale List'!$F$5:$F$421,B9,'Sale List'!$G$5:$G$421,C9) -> 3 | E9: =SUMIFS('Sale List'!$D$5:$D$421,'Sale List'!$F$5:$F$421,B9,'Sale List'!$G$5:$G$421,C9) -> 16424.72
B10: 1095 INVESTMENTS LLC Subtotal | D10: =SUM(D8:D9) -> 48 | E10: =SUM(E8:E9) -> 459498.7
A11: 253 | B11: RAVEN SECURITIES INC | C11: 4 | D11: =COUNTIFS('Sale List'!$F$5:$F$421,B11,'Sale List'!$G$5:$G$421,C11) -> 38 | E11: =SUMIFS('Sale List'!$D$5:$D$421,'Sale List'!$F$5:$F$421,B11,'Sale List'!$G$5:$G$421,C11) -> 270451.61
A12: 253 | B12: RAVEN SECURITIES INC | C12: 5 | D12: =COUNTIFS('Sale List'!$F$5:$F$421,B12,'Sale List'!$G$5:$G$421,C12) -> 7 | E12: =SUMIFS('Sale List'!$D$5:$D$421,'Sale List'!$F$5:$F$421,B12,'Sale List'!$G$5:$G$421,C12) -> 25002.46
A13: 253 | B13: RAVEN SECURITIES INC | C13: 6 | D13: =COUNTIFS('Sale List'!$F$5:$F$421,B13,'Sale List'!$G$5:$G$421,C13) -> 1 | E13: =SUMIFS('Sale List'!$D$5:$D$421,'Sale List'!$F$5:$F$421,B13,'Sale List'!$G$5:$G$421,C13) -> 1768.51
A14: 253 | B14: RAVEN SECURITIES INC | C14: 7 | D14: =COUNTIFS('Sale List'!$F$5:$F$421,B14,'Sale List'!$G$5:$G$421,C14) -> 2 | E14: =SUMIFS('Sale List'!$D$5:$D$421,'Sale List'!$F$5:$F$421,B14,'Sale List'!$G$5:$G$421,C14) -> 2672.21
B15: RAVEN SECURITIES INC Subtotal | D15: =SUM(D11:D14) -> 48 | E15: =SUM(E11:E14) -> 299894.79
A16: 136 | B16: AUCTION Z-2 INC | C16: 4 | D16: =COUNTIFS('Sale List'!$F$5:$F$421,B16,'Sale List'!$G$5:$G$421,C16) -> 46 | E16: =SUMIFS('Sale List'!$D$5:$D$421,'Sale List'!$F$5:$F$421,B16,'Sale List'!$G$5:$G$421,C16) -> 199271.54
A17: 136 | B17: AUCTION Z-2 INC | C17: 5 | D17: =COUNTIFS('Sale List'!$F$5:$F$421,B17,'Sale List'!$G$5:$G$421,C17) -> 7 | E17: =SUMIFS('Sale List'!$D$5:$D$421,'Sale List'!$F$5:$F$421,B17,'Sale List'!$G$5:$G$421,C17) -> 50579.1
B18: AUCTION Z-2 INC Subtotal | D18: =SUM(D16:D17) -> 53 | E18: =SUM(E16:E17) -> 249850.64
A19: 139 | B19: CARNIOLA CAPITAL LLC | C19: 7 | D19: =COUNTIFS('Sale List'!$F$5:$F$421,B19,'Sale List'!$G$5:$G$421,C19) -> 27 | E19: =SUMIFS('Sale List'!$D$5:$D$421,'Sale List'!$F$5:$F$421,B19,'Sale List'!$G$5:$G$421,C19) -> 37194.92
A20: 139 | B20: CARNIOLA CAPITAL LLC | C20: 8 | D20: =COUNTIFS('Sale List'!$F$5:$F$421,B20,'Sale List'!$G$5:$G$421,C20) -> 25 | E20: =SUMIFS('Sale List'!$D$5:$D$421,'Sale List'!$F$5:$F$421,B20,'Sale List'!$G$5:$G$421,C20) -> 32677.8
A21: 139 | B21: CARNIOLA CAPITAL LLC | C21: 9 | D21: =COUNTIFS('Sale List'!$F$5:$F$421,B21,'Sale List'!$G$5:$G$421,C21) -> 10 | E21: =SUMIFS('Sale List'!$D$5:$D$421,'Sale List'!$F$5:$F$421,B21,'Sale List'!$G$5:$G$421,C21) -> 14553.61
B22: CARNIOLA CAPITAL LLC Subtotal | D22: =SUM(D19:D21) -> 62 | E22: =SUM(E19:E21) -> 84426.33
A23: 254 | B23: BERNICE LLC | C23: 0 | D23: =COUNTIFS('Sale List'!$F$5:$F$421,B23,'Sale List'!$G$5:$G$421,C23) -> 6 | E23: =SUMIFS('Sale List'!$D$5:$D$421,'Sale List'!$F$5:$F$421,B23,'Sale List'!$G$5:$G$421,C23) -> 7615.58
A24: 254 | B24: BERNICE LLC | C24: 1 | D24: =COUNTIFS('Sale List'!$F$5:$F$421,B24,'Sale List'!$G$5:$G$421,C24) -> 15 | E24: =SUMIFS('Sale List'!$D$5:$D$421,'Sale List'!$F$5:$F$421,B24,'Sale List'!$G$5:$G$421,C24) -> 12433.68
B25: BERNICE LLC Subtotal | D25: =SUM(D23:D24) -> 21 | E25: =SUM(E23:E24) -> 20049.26
A26: 006 | B26: BYDSOM INC | C26: 9 | D26: =COUNTIFS('Sale List'!$F$5:$F$421,B26,'Sale List'!$G$5:$G$421,C26) -> 12 | E26: =SUMIFS('Sale List'!$D$5:$D$421,'Sale List'!$F$5:$F$421,B26,'Sale List'!$G$5:$G$421,C26) -> 15596.99
B27: BYDSOM INC Subtotal | D27: =SUM(D26:D26) -> 12 | E27: =SUM(E26:E26) -> 15596.99
A28: 241 | B28: AMERICAN TAX LIEN LLC | C28: 7 | D28: =COUNTIFS('Sale List'!$F$5:$F$421,B28,'Sale List'!$G$5:$G$421,C28) -> 2 | E28: =SUMIFS('Sale List'!$D$5:$D$421,'Sale List'!$F$5:$F$421,B28,'Sale List'!$G$5:$G$421,C28) -> 2984.31
A29: 241 | B29: AMERICAN TAX LIEN LLC | C29: 8 | D29: =COUNTIFS('Sale List'!$F$5:$F$421,B29,'Sale List'!$G$5:$G$421,C29) -> 3 | E29: =SUMIFS('Sale List'!$D$5:$D$421,'Sale List'!$F$5:$F$421,B29,'Sale List'!$G$5:$G$421,C29) -> 7560.75
A30: 241 | B30: AMERICAN TAX LIEN LLC | C30: 9 | D30: =COUNTIFS('Sale List'!$F$5:$F$421,B30,'Sale List'!$G$5:$G$421,C30) -> 1 | E30: =SUMIFS('Sale List'!$D$5:$D$421,'Sale List'!$F$5:$F$421,B30,'Sale List'!$G$5:$G$421,C30) -> 1972.02
B31: AMERICAN TAX LIEN LLC Subtotal | D31: =SUM(D28:D30) -> 6 | E31: =SUM(E28:E30) -> 12517.08
A32: 029 | B32: TAX LIEN INVESTMENTS | C32: 4 | D32: =COUNTIFS('Sale List'!$F$5:$F$421,B32,'Sale List'!$G$5:$G$421,C32) -> 5 | E32: =SUMIFS('Sale List'!$D$5:$D$421,'Sale List'!$F$5:$F$421,B32,'Sale List'!$G$5:$G$421,C32) -> 6019.47
B33: TAX LIEN INVESTMENTS Subtotal | D33: =SUM(D32:D32) -> 5 | E33: =SUM(E32:E32) -> 6019.47
A34: 079 | B34: BIG GROVE INVESTMENT | C34: 3 | D34: =COUNTIFS('Sale List'!$F$5:$F$421,B34,'Sale List'!$G$5:$G$421,C34) -> 1 | E34: =SUMIFS('Sale List'!$D$5:$D$421,'Sale List'!$F$5:$F$421,B34,'Sale List'!$G$5:$G$421,C34) -> 309.93
A35: 079 | B35: BIG GROVE INVESTMENT | C35: 4 | D35: =COUNTIFS('Sale List'!$F$5:$F$421,B35,'Sale List'!$G$5:$G$421,C35) -> 4 | E35: =SUMIFS('Sale List'!$D$5:$D$421,'Sale List'!$F$5:$F$421,B35,'Sale List'!$G$5:$G$421,C35) -> 1455.18
A36: 079 | B36: BIG GROVE INVESTMENT | C36: 5 | D36: =COUNTIFS('Sale List'!$F$5:$F$421,B36,'Sale List'!$G$5:$G$421,C36) -> 5 | E36: =SUMIFS('Sale List'!$D$5:$D$421,'Sale List'!$F$5:$F$421,B36,'Sale List'!$G$5:$G$421,C36) -> 1838.51
A37: 079 | B37: BIG GROVE INVESTMENT | C37: 6 | D37: =COUNTIFS('Sale List'!$F$5:$F$421,B37,'Sale List'!$G$5:$G$421,C37) -> 2 | E37: =SUMIFS('Sale List'!$D$5:$D$421,'Sale List'!$F$5:$F$421,B37,'Sale List'!$G$5:$G$421,C37) -> 768.18
A38: 079 | B38: BIG GROVE INVESTMENT | C38: 7 | D38: =COUNTIFS('Sale List'!$F$5:$F$421,B38,'Sale List'!$G$5:$G$421,C38) -> 1 | E38: =SUMIFS('Sale List'!$D$5:$D$421,'Sale List'!$F$5:$F$421,B38,'Sale List'!$G$5:$G$421,C38) -> 145.05
A39: 079 | B39: BIG GROVE INVESTMENT | C39: 8 | D39: =COUNTIFS('Sale List'!$F$5:$F$421,B39,'Sale List'!$G$5:$G$421,C39) -> 2 | E39: =SUMIFS('Sale List'!$D$5:$D$421,'Sale List'!$F$5:$F$421,B39,'Sale List'!$G$5:$G$421,C39) -> 411.33
A40: 079 | B40: BIG GROVE INVESTMENT | C40: 9 | D40: =COUNTIFS('Sale List'!$F$5:$F$421,B40,'Sale List'!$G$5:$G$421,C40) -> 1 | E40: =SUMIFS('Sale List'!$D$5:$D$421,'Sale List'!$F$5:$F$421,B40,'Sale List'!$G$5:$G$421,C40) -> 201.7
B41: BIG GROVE INVESTMENT Subtotal | D41: =SUM(D34:D40) -> 16 | E41: =SUM(E34:E40) -> 5129.88
...

Sheet Bidder x Rate Matrix
A1: Total Amount by Bidder (rows) and Bid % (columns)
B2: 0 | C2: 1 | D2: 3 | E2: 4 | F2: 5 | G2: 6 | H2: 7 | I2: 8 | J2: 9
A3: Buyer Name | B3: 0% | C3: 1% | D3: 3% | E3: 4% | F3: 5% | G3: 6% | H3: 7% | I3: 8% | J3: 9% | K3: Total
A4: PRIVATE EQUITY GROUP | B4: =SUMIFS('Sale List'!$D$5:$D$421,'Sale List'!$F$5:$F$421,$A4,'Sale List'!$G$5:$G$421,B$2) -> 0 | C4: =SUMIFS('Sale List'!$D$5:$D$421,'Sale List'!$F$5:$F$421,$A4,'Sale List'!$G$5:$G$421,C$2) -> 0 | D4: =SUMIFS('Sale List'!$D$5:$D$421,'Sale List'!$F$5:$F$421,$A4,'Sale List'!$G$5:$G$421,D$2) -> 0 | E4: =SUMIFS('Sale List'!$D$5:$D$421,'Sale List'!$F$5:$F$421,$A4,'Sale List'!$G$5:$G$421,E$2) -> 112371.05 | F4: =SUMIFS('Sale List'!$D$5:$D$421,'Sale List'!$F$5:$F$421,$A4,'Sale List'!$G$5:$G$421,F$2) -> 974337.24 | G4: =SUMIFS('Sale List'!$D$5:$D$421,'Sale List'!$F$5:$F$421,$A4,'Sale List'!$G$5:$G$421,G$2) -> 51946.58 | H4: =SUMIFS('Sale List'!$D$5:$D$421,'Sale List'!$F$5:$F$421,$A4,'Sale List'!$G$5:$G$421,H$2) -> 0 | I4: =SUMIFS('Sale List'!$D$5:$D$421,'Sale List'!$F$5:$F$421,$A4,'Sale List'!$G$5:$G$421,I$2) -> 0 | J4: =SUMIFS('Sale List'!$D$5:$D$421,'Sale List'!$F$5:$F$421,$A4,'Sale List'!$G$5:$G$421,J$2) -> 0 | K4: =SUM(B4:J4) -> 1138654.9
A5: 1095 INVESTMENTS LLC | B5: =SUMIFS('Sale List'!$D$5:$D$421,'Sale List'!$F$5:$F$421,$A5,'Sale List'!$G$5:$G$421,B$2) -> 0 | C5: =SUMIFS('Sale List'!$D$5:$D$421,'Sale List'!$F$5:$F$421,$A5,'Sale List'!$G$5:$G$421,C$2) -> 0 | D5: =SUMIFS('Sale List'!$D$5:$D$421,'Sale List'!$F$5:$F$421,$A5,'Sale List'!$G$5:$G$421,D$2) -> 0 | E5: =SUMIFS('Sale List'!$D$5:$D$421,'Sale List'!$F$5:$F$421,$A5,'Sale List'!$G$5:$G$421,E$2) -> 0 | F5: =SUMIFS('Sale List'!$D$5:$D$421,'Sale List'!$F$5:$F$421,$A5,'Sale List'!$G$5:$G$421,F$2) -> 443073.98 | G5: =SUMIFS('Sale List'!$D$5:$D$421,'Sale List'!$F$5:$F$421,$A5,'Sale List'!$G$5:$G$421,G$2) -> 16424.72 | H5: =SUMIFS('Sale List'!$D$5:$D$421,'Sale List'!$F$5:$F$421,$A5,'Sale List'!$G$5:$G$421,H$2) -> 0 | I5: =SUMIFS('Sale List'!$D$5:$D$421,'Sale List'!$F$5:$F$421,$A5,'Sale List'!$G$5:$G$421,I$2) -> 0 | J5: =SUMIFS('Sale List'!$D$5:$D$421,'Sale List'!$F$5:$F$421,$A5,'Sale List'!$G$5:$G$421,J$2) -> 0 | K5: =SUM(B5:J5) -> 459498.7
A6: RAVEN SECURITIES INC | B6: =SUMIFS('Sale List'!$D$5:$D$421,'Sale List'!$F$5:$F$421,$A6,'Sale List'!$G$5:$G$421,B$2) -> 0 | C6: =SUMIFS('Sale List'!$D$5:$D$421,'Sale List'!$F$5:$F$421,$A6,'Sale List'!$G$5:$G$421,C$2) -> 0 | D6: =SUMIFS('Sale List'!$D$5:$D$421,'Sale List'!$F$5:$F$421,$A6,'Sale List'!$G$5:$G$421,D$2) -> 0 | E6: =SUMIFS('Sale List'!$D$5:$D$421,'Sale List'!$F$5:$F$421,$A6,'Sale List'!$G$5:$G$421,E$2) -> 270451.61 | F6: =SUMIFS('Sale List'!$D$5:$D$421,'Sale List'!$F$5:$F$421,$A6,'Sale List'!$G$5:$G$421,F$2) -> 25002.46 | G6: =SUMIFS('Sale List'!$D$5:$D$421,'Sale List'!$F$5:$F$421,$A6,'Sale List'!$G$5:$G$421,G$2) -> 1768.51 | H6: =SUMIFS('Sale List'!$D$5:$D$421,'Sale List'!$F$5:$F$421,$A6,'Sale List'!$G$5:$G$421,H$2) -> 2672.21 | I6: =SUMIFS('Sale List'!$D$5:$D$421,'Sale List'!$F$5:$F$421,$A6,'Sale List'!$G$5:$G$421,I$2) -> 0 | J6: =SUMIFS('Sale List'!$D$5:$D$421,'Sale List'!$F$5:$F$421,$A6,'Sale List'!$G$5:$G$421,J$2) -> 0 | K6: =SUM(B6:J6) -> 299894.79
A7: AUCTION Z-2 INC | B7: =SUMIFS('Sale List'!$D$5:$D$421,'Sale List'!$F$5:$F$421,$A7,'Sale List'!$G$5:$G$421,B$2) -> 0 | C7: =SUMIFS('Sale List'!$D$5:$D$421,'Sale List'!$F$5:$F$421,$A7,'Sale List'!$G$5:$G$421,C$2) -> 0 | D7: =SUMIFS('Sale List'!$D$5:$D$421,'Sale List'!$F$5:$F$421,$A7,'Sale List'!$G$5:$G$421,D$2) -> 0 | E7: =SUMIFS('Sale List'!$D$5:$D$421,'Sale List'!$F$5:$F$421,$A7,'Sale List'!$G$5:$G$421,E$2) -> 199271.54 | F7: =SUMIFS('Sale List'!$D$5:$D$421,'Sale List'!$F$5:$F$421,$A7,'Sale List'!$G$5:$G$421,F$2) -> 50579.1 | G7: =SUMIFS('Sale List'!$D$5:$D$421,'Sale List'!$F$5:$F$421,$A7,'Sale List'!$G$5:$G$421,G$2) -> 0 | H7: =SUMIFS('Sale List'!$D$5:$D$421,'Sale List'!$F$5:$F$421,$A7,'Sale List'!$G$5:$G$421,H$2) -> 0 | I7: =SUMIFS('Sale List'!$D$5:$D$421,'Sale List'!$F$5:$F$421,$A7,'Sale List'!$G$5:$G$421,I$2) -> 0 | J7: =SUMIFS('Sale List'!$D$5:$D$421,'Sale List'!$F$5:$F$421,$A7,'Sale List'!$G$5:$G$421,J$2) -> 0 | K7: =SUM(B7:J7) -> 249850.64
A8: CARNIOLA CAPITAL LLC | B8: =SUMIFS('Sale List'!$D$5:$D$421,'Sale List'!$F$5:$F$421,$A8,'Sale List'!$G$5:$G$421,B$2) -> 0 | C8: =SUMIFS('Sale List'!$D$5:$D$421,'Sale List'!$F$5:$F$421,$A8,'Sale List'!$G$5:$G$421,C$2) -> 0 | D8: =SUMIFS('Sale List'!$D$5:$D$421,'Sale List'!$F$5:$F$421,$A8,'Sale List'!$G$5:$G$421,D$2) -> 0 | E8: =SUMIFS('Sale List'!$D$5:$D$421,'Sale List'!$F$5:$F$421,$A8,'Sale List'!$G$5:$G$421,E$2) -> 0 | F8: =SUMIFS('Sale List'!$D$5:$D$421,'Sale List'!$F$5:$F$421,$A8,'Sale List'!$G$5:$G$421,F$2) -> 0 | G8: =SUMIFS('Sale List'!$D$5:$D$421,'Sale List'!$F$5:$F$421,$A8,'Sale List'!$G$5:$G$421,G$2) -> 0 | H8: =SUMIFS('Sale List'!$D$5:$D$421,'Sale List'!$F$5:$F$421,$A8,'Sale List'!$G$5:$G$421,H$2) -> 37194.92 | I8: =SUMIFS('Sale List'!$D$5:$D$421,'Sale List'!$F$5:$F$421,$A8,'Sale List'!$G$5:$G$421,I$2) -> 32677.8 | J8: =SUMIFS('Sale List'!$D$5:$D$421,'Sale List'!$F$5:$F$421,$A8,'Sale List'!$G$5:$G$421,J$2) -> 14553.61 | K8: =SUM(B8:J8) -> 84426.33
A9: BERNICE LLC | B9: =SUMIFS('Sale List'!$D$5:$D$421,'Sale List'!$F$5:$F$421,$A9,'Sale List'!$G$5:$G$421,B$2) -> 7615.58 | C9: =SUMIFS('Sale List'!$D$5:$D$421,'Sale List'!$F$5:$F$421,$A9,'Sale List'!$G$5:$G$421,C$2) -> 12433.68 | D9: =SUMIFS('Sale List'!$D$5:$D$421,'Sale List'!$F$5:$F$421,$A9,'Sale List'!$G$5:$G$421,D$2) -> 0 | E9: =SUMIFS('Sale List'!$D$5:$D$421,'Sale List'!$F$5:$F$421,$A9,'Sale List'!$G$5:$G$421,E$2) -> 0 | F9: =SUMIFS('Sale List'!$D$5:$D$421,'Sale List'!$F$5:$F$421,$A9,'Sale List'!$G$5:$G$421,F$2) -> 0 | G9: =SUMIFS('Sale List'!$D$5:$D$421,'Sale List'!$F$5:$F$421,$A9,'Sale List'!$G$5:$G$421,G$2) -> 0 | H9: =SUMIFS('Sale List'!$D$5:$D$421,'Sale List'!$F$5:$F$421,$A9,'Sale List'!$G$5:$G$421,H$2) -> 0 | I9: =SUMIFS('Sale List'!$D$5:$D$421,'Sale List'!$F$5:$F$421,$A9,'Sale List'!$G$5:$G$421,I$2) -> 0 | J9: =SUMIFS('Sale List'!$D$5:$D$421,'Sale List'!$F$5:$F$421,$A9,'Sale List'!$G$5:$G$421,J$2) -> 0 | K9: =SUM(B9:J9) -> 20049.26
A10: BYDSOM INC | B10: =SUMIFS('Sale List'!$D$5:$D$421,'Sale List'!$F$5:$F$421,$A10,'Sale List'!$G$5:$G$421,B$2) -> 0 | C10: =SUMIFS('Sale List'!$D$5:$D$421,'Sale List'!$F$5:$F$421,$A10,'Sale List'!$G$5:$G$421,C$2) -> 0 | D10: =SUMIFS('Sale List'!$D$5:$D$421,'Sale List'!$F$5:$F$421,$A10,'Sale List'!$G$5:$G$421,D$2) -> 0 | E10: =SUMIFS('Sale List'!$D$5:$D$421,'Sale List'!$F$5:$F$421,$A10,'Sale List'!$G$5:$G$421,E$2) -> 0 | F10: =SUMIFS('Sale List'!$D$5:$D$421,'Sale List'!$F$5:$F$421,$A10,'Sale List'!$G$5:$G$421,F$2) -> 0 | G10: =SUMIFS('Sale List'!$D$5:$D$421,'Sale List'!$F$5:$F$421,$A10,'Sale List'!$G$5:$G$421,G$2) -> 0 | H10: =SUMIFS('Sale List'!$D$5:$D$421,'Sale List'!$F$5:$F$421,$A10,'Sale List'!$G$5:$G$421,H$2) -> 0 | I10: =SUMIFS('Sale List'!$D$5:$D$421,'Sale List'!$F$5:$F$421,$A10,'Sale List'!$G$5:$G$421,I$2) -> 0 | J10: =SUMIFS('Sale List'!$D$5:$D$421,'Sale List'!$F$5:$F$421,$A10,'Sale List'!$G$5:$G$421,J$2) -> 15596.99 | K10: =SUM(B10:J10) -> 15596.99
A11: AMERICAN TAX LIEN LLC | B11: =SUMIFS('Sale List'!$D$5:$D$421,'Sale List'!$F$5:$F$421,$A11,'Sale List'!$G$5:$G$421,B$2) -> 0 | C11: =SUMIFS('Sale List'!$D$5:$D$421,'Sale List'!$F$5:$F$421,$A11,'Sale List'!$G$5:$G$421,C$2) -> 0 | D11: =SUMIFS('Sale List'!$D$5:$D$421,'Sale List'!$F$5:$F$421,$A11,'Sale List'!$G$5:$G$421,D$2) -> 0 | E11: =SUMIFS('Sale List'!$D$5:$D$421,'Sale List'!$F$5:$F$421,$A11,'Sale List'!$G$5:$G$421,E$2) -> 0 | F11: =SUMIFS('Sale List'!$D$5:$D$421,'Sale List'!$F$5:$F$421,$A11,'Sale List'!$G$5:$G$421,F$2) -> 0 | G11: =SUMIFS('Sale List'!$D$5:$D$421,'Sale List'!$F$5:$F$421,$A11,'Sale List'!$G$5:$G$421,G$2) -> 0 | H11: =SUMIFS('Sale List'!$D$5:$D$421,'Sale List'!$F$5:$F$421,$A11,'Sale List'!$G$5:$G$421,H$2) -> 2984.31 | I11: =SUMIFS('Sale List'!$D$5:$D$421,'Sale List'!$F$5:$F$421,$A11,'Sale List'!$G$5:$G$421,I$2) -> 7560.75 | J11: =SUMIFS('Sale List'!$D$5:$D$421,'Sale List'!$F$5:$F$421,$A11,'Sale List'!$G$5:$G$421,J$2) -> 1972.02 | K11: =SUM(B11:J11) -> 12517.08
A12: TAX LIEN INVESTMENTS | B12: =SUMIFS('Sale List'!$D$5:$D$421,'Sale List'!$F$5:$F$421,$A12,'Sale List'!$G$5:$G$421,B$2) -> 0 | C12: =SUMIFS('Sale List'!$D$5:$D$421,'Sale List'!$F$5:$F$421,$A12,'Sale List'!$G$5:$G$421,C$2) -> 0 | D12: =SUMIFS('Sale List'!$D$5:$D$421,'Sale List'!$F$5:$F$421,$A12,'Sale List'!$G$5:$G$421,D$2) -> 0 | E12: =SUMIFS('Sale List'!$D$5:$D$421,'Sale List'!$F$5:$F$421,$A12,'Sale List'!$G$5:$G$421,E$2) -> 6019.47 | F12: =SUMIFS('Sale List'!$D$5:$D$421,'Sale List'!$F$5:$F$421,$A12,'Sale List'!$G$5:$G$421,F$2) -> 0 | G12: =SUMIFS('Sale List'!$D$5:$D$421,'Sale List'!$F$5:$F$421,$A12,'Sale List'!$G$5:$G$421,G$2) -> 0 | H12: =SUMIFS('Sale List'!$D$5:$D$421,'Sale List'!$F$5:$F$421,$A12,'Sale List'!$G$5:$G$421,H$2) -> 0 | I12: =SUMIFS('Sale List'!$D$5:$D$421,'Sale List'!$F$5:$F$421,$A12,'Sale List'!$G$5:$G$421,I$2) -> 0 | J12: =SUMIFS('Sale List'!$D$5:$D$421,'Sale List'!$F$5:$F$421,$A12,'Sale List'!$G$5:$G$421,J$2) -> 0 | K12: =SUM(B12:J12) -> 6019.47
A13: BIG GROVE INVESTMENT | B13: =SUMIFS('Sale List'!$D$5:$D$421,'Sale List'!$F$5:$F$421,$A13,'Sale List'!$G$5:$G$421,B$2) -> 0 | C13: =SUMIFS('Sale List'!$D$5:$D$421,'Sale List'!$F$5:$F$421,$A13,'Sale List'!$G$5:$G$421,C$2) -> 0 | D13: =SUMIFS('Sale List'!$D$5:$D$421,'Sale List'!$F$5:$F$421,$A13,'Sale List'!$G$5:$G$421,D$2) -> 309.93 | E13: =SUMIFS('Sale List'!$D$5:$D$421,'Sale List'!$F$5:$F$421,$A13,'Sale List'!$G$5:$G$421,E$2) -> 1455.18 | F13: =SUMIFS('Sale List'!$D$5:$D$421,'Sale List'!$F$5:$F$421,$A13,'Sale List'!$G$5:$G$421,F$2) -> 1838.51 | G13: =SUMIFS('Sale List'!$D$5:$D$421,'Sale List'!$F$5:$F$421,$A13,'Sale List'!$G$5:$G$421,G$2) -> 768.18 | H13: =SUMIFS('Sale List'!$D$5:$D$421,'Sale List'!$F$5:$F$421,$A13,'Sale List'!$G$5:$G$421,H$2) -> 145.05 | I13: =SUMIFS('Sale List'!$D$5:$D$421,'Sale List'!$F$5:$F$421,$A13,'Sale List'!$G$5:$G$421,I$2) -> 411.33 | J13: =SUMIFS('Sale List'!$D$5:$D$421,'Sale List'!$F$5:$F$421,$A13,'Sale List'!$G$5:$G$421,J$2) -> 201.7 | K13: =SUM(B13:J13) -> 5129.88
A14: TOTAL | B14: =SUM(B4:B13) -> 7615.58 | C14: =SUM(C4:C13) -> 12433.68 | D14: =SUM(D4:D13) -> 309.93 | E14: =SUM(E4:E13) -> 589568.85 | F14: =SUM(F4:F13) -> 1494831.3 | G14: =SUM(G4:G13) -> 70907.99 | H14: =SUM(H4:H13) -> 42996.49 | I14: =SUM(I4:I13) -> 40649.88 | ... K14: =SUM(K4:K13) -> 2291638
